Workbook

Sheet Instruction1
A1: คำแนะนำไฟล์ข้อมูล
A2: Column(คอลัมน์) สีส้ม | B2: = | C2: Store name (ชื่อสาขา)
A3: Column(คอลัมน์) สีเทา | B3: = | C3: Day (วัน), Month (เดือน)
A4: Column(คอลัมน์) สีเขียว | B4: = | C4: ข้อมูลเกี่ยวกับ Sales(ยอดขาย)
A5: Column(คอลัมน์) สีเหลือง | B5: = | C5: ข้อมูลเกี่ยวกับ Ticket Count (TC) จำนวนลูกค้า
A6: Column(คอลัมน์) สีฟ้า | B6: = | C6: ข้อมูลเกี่ยวกับ Ticket Average (TA) ค่าเฉลี่ยต่อบิลการขาย(บาท)
A7: Column(คอลัมน์) สีม่วง | B7: = | C7: ข้อมูลเกี่ยวกับ Working Hour (ชั่วโมงการทำงาน)
A8: Column(คอลัมน์) สีส้ม | B8: = | C8: ข้อมูลเกี่ยวกับ Promotion (โปรโมชั่น)
A9: Column(คอลัมน์) สีเทา | B9: = | C9: Total (ข้อมูลสรุปรวมแต่ละเรื่อง)
A10: Column(คอลัมน์) สีแดง | B10: = | C10: จำนวน Duty Team ที่มีอยู่ที่ร้าน และ Pay Per Hour(PPH) ค่าชั่วโมงเฉลี่ยที่จ่ายต่อชั่วโมง
A12: ข้อมูลพื้นฐาน Sales(ยอดขาย)
A13: Last Year Sales (Daily) | B13: = | C13: ข้อมูลยอดขายปีที่แล้ว รายวัน
A14: Last Year Sales MTD (Month To Date) | B14: = | C14: ข้อมูลยอดขายปีที่แล้วในเดือนจนถึงปัจจุบัน
A15: Target Sales (Incentive) Daily | B15: = | C15: เป้าหมายยอดขายอินเซนทีฟรายวัน
A16: Target Sales MTD (Incentive) | B16: = | C16: เป้าหมายยอดขายอินเซนทีฟในเดือนจนถึงปัจจุบัน
A17: Forecast Sales From NBO | B17: = | C17: ข้อมูลคาดการณ์ยอดขายจากระบบ NBO
A18: Actual Sales (Daily) | B18: = | C18: ยอดขายที่ขายได้จริงรายวัน
A19: Actual Sales MTD | B19: = | C19: ยอดขายที่ที่ขายได้จริงในเดือนจนถึงปัจจุบัน
A20: Varaince From Target | B20: = | C20: ผลต่างยอดขายเทียบ Target รายวัน
A21: Varaince MTD | B21: = | C21: ผลต่างยอดขายเทียบ Target ในเดือนจนถึงปัจจุบัน
A22: Sales Delivery (Daily) | B22: = | C22: ข้อมูลยอดขาย Delivery ทุก Food Aggregators
A23: Sales Delivery MTD | B23: = | C23: ข้อมูลยอดขาย Delivery ทุก Food Aggregators ในเดือนจนถึงปัจจุบัน
A24: Achive Incentive Target% | B24: = | C24: เปอร์เซ็นต์ยอดขายเทียบ Target อินเซนทีฟ คำนวณเป็นเปอร์เซ็นต์
... A29: Waste Daily (%) | B29: = | C29: ยอดทิ้งสินค้ารายวันคิดเป็นเปอร์เซ็นต์
A31: ข้อมูลพื้นฐาน Ticket Count (TC) จำนวนลูกค้า
A32: Last year TC (Daily) | B32: = | C32: ข้อมูลจำนวนลูกค้าปีที่แล้ว รายวัน
A33: Last year TC MTD (Month To Date) | B33: = | C33: ข้อมูลจำนวนลูกค้าปีที่แล้วในเดือนจนถึงปัจจุบัน
A34: Target TC (Daily) | B34: = | C34: เป้าหมายจำนวนลูกค้ารายวัน
A35: Target TC MTD | B35: = | C35: เป้าหมายจำนวนลูกค้าในเดือนจนถึงปัจจุบัน
A36: Actual TC (Daily) | B36: = | C36: จำนวนลูกค้าจริงที่เข้าใช้บริการรายวัน
A37: Actual TC MTD | B37: = | C37: จำนวนลูกค้าจริงที่เข้าใช้บริการในเดือนจนถึงปัจจุบัน
A38: Varaince From Target | B38: = | C38: ผลต่างจำนวนลูกค้าเทียบ Target รายวัน
A39: Varaince From Last year | B39: = | C39: ผลต่างจำนวนลูกค้าเทียบปีที่แล้ว
A40: Comp TC % | B40: = | C40: เปรียบเทียบจำนวนลูกค้าปีที่แล้วคิดเป็นเปอร์เซ็นต์
A42: ข้อมูลพื้นฐาน Ticket Average (TA) ค่าเฉลี่ยต่อบิลการขาย(บาท)
A43: Last year TA | B43: = | C43: ข้อมูลค่าเฉลี่ยต่อบิลการขายปีที่แล้วรายวัน
A44: Target TA | B44: = | C44: ข้อมูลเป้าหมายค่าเฉลี่ยต่อบิลการขายรายวัน
A45: Actual TA | B45: = | C45: ค่าเฉลี่ยต่อบิลการขายที่ทำได้จริงรายวัน
A46: Variance Target VS Actual | B46: = | C46: ผลต่างค่าเฉลี่ยต่อบิลการขาย เป้าหมายเปรียบเทียบกับค่าเฉลี่ยต่อบิลที่ทำได้จริงรายวัน
A48: ข้อมูลพื้นฐาน Working Hour (ชั่วโมงการทำงาน)
...

Sheet Instruction(สูตร)
A1: คำอธิบายวิธีการคิดคำนวน
A2: Pay Per Hour(PPH) ค่าชั่วโมงเฉลี่ยที่จ่ายต่อชั่วโมง | B2: = | C2: นำค่าจ้างพนักงานใน P&L COL บาท ของเดือนล่าสุด
B3: = | C3: ตัวอย่าง Duty Team 4 คน ใน 1 เดือน จะมีวันหยุด 4 วัน ต่อ 1 คน=วันทำงาน 26 วัน คูณ 8 ชั่วโมง (26*8=208)*4 คน=832 ชั่วโมงต่อเดือน (A) ตัวอย่าง FT=2 คน ใน 1 เดือน จะมีวันหยุด 4 วัน ต่อ 1 คน=วันทำงาน 26 วัน คูณ 8 ชั่วโมง (26*8=208)*2 คน=416 ชั่วโมงต่อเดือน (B) นำ ชั่วโมงพนักงาน Part Time ของเดือนล่าสุดหักชั่วโมง Duty Team ลบออก ดูข้อมูลได้จาก NBO 1.02 Time Clock Detail หน้าสุดท้าย (C)
B4: = | C4: วิธีการคำนวณ นำ COL บาท หาร ด้วยชั่วโมงการทำงานทั้งหมด (A+B+C) (250,000 บาท) หาร (832+416+2,299=3,547 ชั่วโมง) (250,000/3,547=70 บาท Pay Per Hour(PPH) ค่าชั่วโมงเฉลี่ยที่จ่ายต่อชั่วโมง)
A6: ข้อมูลพื้นฐานสูตร Sales(ยอดขาย)
A7: Last Year Sales MTD (Month To Date) | B7: = | C7: นำยอดขาย Last Year(Daily) มาบวกกันตั้งแต่วันที่ 1 ถึงวันปัจจุบัน
A8: Target Sales MTD (Incentive) | B8: = | C8: นำ Target (Incentive) Daily รายวัน มาบวกกันตั้งแต่วันที่ 1 ถึงวันปัจจุบัน
A9: Actual Sales MTD | B9: = | C9: นำ ยอดขาย Actual Sales (Daily) มาบวกกันตั้งแต่วันที่ 1 ถึงวันปัจจุบัน
A10: Varaince From Target | B10: = | C10: นำ Actual Sales (Daily) ลบ Target (Incentive) วันต่อวัน
A11: Varaince MTD | B11: = | C11: นำผลต่างยอดขายเทียบ Target ในแต่ละวันมาบวกกัน ตั้งแต่วันที่ 1 ถึงวันปัจจุบัน
A12: Sales Delivery MTD | B12: = | C12: นำ ยอดขาย Delivery ทุก Food Agregators มาบวกกันตั้งแต่วันที่ 1 ถึงวันปัจจุบัน
A13: Achive Incentive Target% | B13: = | C13: นำ Varaince MTD หาร Target MTD (Incentive) กดเปอร์เซ็นต์
A14: Varaince From Forecast | B14: = | C14: นำ Actual Sales (Daily) ลบ Forecast Sales From NBO
A15: % | B15: = | C15: นำ Varaince From Forecast หาร Forecast Sales From NBO กดเปอร์เซ็นต์
A16: Comp Sales % | B16: = | C16: นำ Actual Sales MTD ลบ Last Year MTD และหารด้วย Last Year MTD กดเปอร์เซ็นต์
A17: Waste Daily (%) | B17: = | C17: นำ Waste Daily (Bath) หาร Actual Sales (Daily) กดเปอร์เซ็นต์
A19: ข้อมูลพื้นฐานสูตร Ticket Count (TC) จำนวนลูกค้า
A20: Last year TC MTD (Month To Date) | B20: = | C20: นำข้อมูลจำนวนลูกค้า Last year (Daily) มาบวกกันตั้งแต่วันที่ 1 ถึงวันปัจจุบัน
A21: Target TC MTD | B21: = | C21: นำ Target (Daily) มาบวกกันตั้งแต่วันที่ 1 ถึงวันปัจจุบัน
A22: Actual TC MTD | B22: = | C22: นำ Actual (Daily) มาบวกกันตั้งแต่วันที่ 1 ถึงวันปัจจุบัน
A23: Varaince From Target | B23: = | C23: นำ Actual MTD ลบ Target MTD
A24: Varaince From Last year | B24: = | C24: นำ Actual MTD ลบ Last year MTD
A25: Comp TC % | B25: = | C25: นำ Actual MTD ลบ Last year MTD และหารด้วย Last Year MTD กดเปอร์เซ็นต์
A27: ข้อมูลพื้นฐานสูตร Ticket Average (TA) ค่าเฉลี่ยต่อบิลการขาย(บาท)
A28: Last year TA | B28: = | C28: นำ ยอดขาย Last Year(Daily) หาร จำนวนลูกค้า Last year (Daily)
A29: Target TA | B29: = | C29: นำ ยอดขาย Target (Incentive) Daily หาร จำนวนลูกค้า Target (Daily)
A30: Actual TA | B30: = | C30: นำ ยอดขาย Actual Sales (Daily) หาร จำนวนลูกค้า Actual (Daily)
A31: Variance Target VS Actual | B31: = | C31: นำ Actual TA ลบ Target TA
A33: ข้อมูลพื้นฐาน Working Hour (ชั่วโมงการทำงาน)
A34: (Month To Date) MTD Roster Working Hours | B34: = | C34: นำ Roster Commit From Area รายวัน มาบวกกันตั้งแต่วันที่ 1 ถึงวันปัจจุบัน
A35: ชั่วโมงการทำงาน Duty Team (ห้ามแก้ไข) | B35: = | C35: นำ จำนวน Duty Team ที่มีอยู่ที่ร้าน คูณ 8 (ชั่วโมง)
A36: Summary Hours Total | B36: = | C36: นำ Actual Hour (PT+FT) บวก OT Hour
A37: MTD Working Hours | B37: = | C37: นำ ชั่วโมง Summary Total รายวัน มาบวกกันตั้งแต่วันที่ 1 ถึงวันปัจจุบัน
A38: Variance Hours | B38: = | C38: นำ ชั่วโมง Summary Total ลบ Roster Commit From Area
A39: COL (Bath) | B39: = | C39: นำ ชั่วโมงการทำงาน Duty Team (ห้ามแก้ไข) บวก Actual Hour (PT+FT) บวก OT Hour คูณ PPH ค่าชั่วโมงเฉลี่ยที่จ่ายต่อชั่วโมง
A40: MTD COL | B40: = | C40: นำ COL (Bath) รายวัน มาบวกกันตั้งแต่วันที่ 1 ถึงวันปัจจุบัน
A41: COL (%) | B41: = | C41: นำ MTD COL หาร Actual Sales MTD กดเปอร์เซ็นต์
A42: Actual TCMH | B42: = | C42: นำ จำนวนลูกค้า Actual MTD หาร MTD Working Hour
A44: ข้อมูลพื้นฐานสูตร Promotion (โปรโมชั่นที่ต้องการบันทึกเพื่อนำมาวิเคราะห์ข้อมูล)
A45: MTD Value Meal | B45: = | C45: นำ Value Meal Set รายวัน มาบวกกันตั้งแต่วันที่ 1 ถึงวันปัจจุบัน
...

Sheet Sales Management Sheet
C1: Store name : | D1: Grand Diamond | R1: Target Waste 0.75% | AE1: จำนวน Duty Team ที่มีอยู่ที่ร้าน ==>> | AI1: 6 | AL1: PPH ค่าชั่วโมงเฉลี่ยที่จ่ายต่อชั่วโมง ==>> | AQ1: 84 | AS1: Target TCMH 4.4
A2: Day | B2: Month | C2: Sales | T2: TC | AC2: TA | AG2: 4 | AT2: Promotion
C3: Last Year Sales (Daily) | D3: Last Year Sales MTD | E3: Target Sales (Incentive) Daily | F3: Target Sales MTD (Incentive) | G3: Forecast Sales From NBO | H3: Actual Sales (Daily) | I3: Actual Sales MTD | J3: Varaince From Target | K3: Varaince MTD | L3: Sales Delivery (Daily) | M3: Sales Delivery MTD | N3: Achive Incentive Target% | O3: Varaince From Forecast | P3: % | Q3: Comp Sales % | R3: Waste Daily (Bath) | S3: Waste Daily (%) | T3: Last year TC (Daily) | U3: Last year TC MTD | V3: Target TC (Daily) | W3: Target TC MTD | X3: Actual TC (Daily) | Y3: Actual TC MTD | Z3: Varaince From Target | AA3: Varaince From Last year | AB3: Comp TC % | AC3: Last year TA | AD3: Target TA | AE3: Actual TA | AF3: Variance Target VS Actual | AG3: Recommend Hours (ชั่วโมงจากระบบ NBO) | AH3: Roster Commit From Area | AI3: MTD Roster Working Hours | AJ3: ชั่วโมงการทำงาน Duty Team (ห้ามแก้ไข) | AK3: Actual Hours (PT+FT) | AL3: OT Hours | AM3: Summary Hours Total | AN3: MTD Working Hours | AO3: Variance Hours | AP3: COL(Bath) | AQ3: MTD COL | AR3: COL(%) | AS3: Actual TCMH | AT3: Value Meal Set | AU3: MTD Value Meal | AV3: %Value Meal | AW3: UP Size | AX3: MTD UP Size | AY3: %UP Size | AZ3: Add Cheese (จำนวนแผ่น) | BA3: MTD Add Cheese | BB3: %Add Cheese | BC3: Other (New promotion) | BD3: MTD | BE3: % | BF3: Other (New promotion) | BG3: MTD | BH3: %
A4: =B4 -> 46113 | B4: 46113 | C4: 91837 | D4: =C4 -> 91837 | E4: 95000 | F4: =E4 -> 95000 | G4: 83967 | I4: =H4 -> 0 | J4: =H4-E4 -> -95000 | K4: =J4 -> -95000 | M4: =L5+L4 -> 0 | N4: =K4/F4 -> -1 | O4: =H4-G4 -> -83967 | P4: =IF(ISERROR(O4/G4),0,O4/G4) -> -1 | Q4: =(I4-D4)/D4 -> -1 | S4: =R4/H4 -> #DIV/0! | T4: 320 | U4: =T4 -> 320 | V4: 340 | W4: =V4 -> 340 | Y4: =X4 -> 0 | Z4: =Y4-W4 -> -340 | AA4: =Y4-U4 -> -320 | AB4: =(Y4-U4)/U4 -> -1 | AC4: =C4/T4 -> 286.99063 | AD4: =E4/V4 -> 279.41176 | AE4: =H4/X4 -> #DIV/0! | AF4: =AE4-AD4 -> #DIV/0! | AH4: 88 | AI4: =AH4 -> 88 | AJ4: =$AI$1*8 -> 48 | AL4: 0 | AM4: =SUM(AK4:AL4) -> 0 | AN4: =AM4 -> 0 | AO4: =SUM(AM4)-AH4 -> -88 | AP4: =SUM(AJ4:AL4)*AQ$1 -> 4032 | AQ4: =AP4 -> 4032 | AR4: =IF(ISERROR(AQ4/I4),0,AQ4/I4) -> 0 | AS4: =Y4/AN4 -> #DIV/0! | AU4: =AT4 -> 0 | AV4: =AU4/Y4 -> #DIV/0! | AX4: =AW4 -> 0 | AY4: =AX4/Y4 -> #DIV/0! | BA4: =AZ4 -> 0 | BB4: =BA4/Y4 -> #DIV/0! | BD4: =BC4 -> 0 | BE4: =BD4/Y4 -> #DIV/0! | BG4: =BF4 -> 0 | BH4: =BG4/Y4 -> #DIV/0!
A5: =B5 -> 46114 | B5: =B4+1 -> 46114 | C5: 66417 | D5: =C5+D4 -> 158254 | E5: 95000 | F5: =E5+F4 -> 190000 | G5: 86741 | I5: =H5+I4 -> 0 | J5: =H5-E5 -> -95000 | K5: =J5+K4 -> -190000 | M5: =L6+M4 -> 0 | N5: =K5/F5 -> -1 | O5: =H5-G5 -> -86741 | P5: =IF(ISERROR(O5/G5),0,O5/G5) -> -1 | Q5: =(I5-D5)/D5 -> -1 | S5: =R5/H5 -> #DIV/0! | T5: 275 | U5: =T5+U4 -> 595 | V5: 340 | W5: =V5+W4 -> 680 | Y5: =X5+Y4 -> 0 | Z5: =Y5-W5 -> -680 | AA5: =Y5-U5 -> -595 | AB5: =(Y5-U5)/U5 -> -1 | AC5: =C5/T5 -> 241.51636 | AD5: =E5/V5 -> 279.41176 | AE5: =H5/X5 -> #DIV/0! | AF5: =AE5-AD5 -> #DIV/0! | AH5: 88 | AI5: =AH5+AI4 -> 176 | AJ5: =$AI$1*8 -> 48 | AL5: 0 | AM5: =SUM(AK5:AL5) -> 0 | AN5: =AM5+AN4 -> 0 | AO5: =SUM(AM5)-AH5 -> -88 | AP5: =SUM(AJ5:AL5)*AQ$1 -> 4032 | AQ5: =SUM(AP5,AQ4) -> 8064 | AR5: =IF(ISERROR(AQ5/I5),0,AQ5/I5) -> 0 | AS5: =Y5/AN5 -> #DIV/0! | AU5: =AT5+AU4 -> 0 | AV5: =AU5/Y5 -> #DIV/0! | AX5: =AW5+AX4 -> 0 | AY5: =AX5/Y5 -> #DIV/0! | BA5: =AZ5+BA4 -> 0 | BB5: =BA5/Y5 -> #DIV/0! | BD5: =BC5+BD4 -> 0 | BE5: =BD5/Y5 -> #DIV/0! | BG5: =BF5+BG4 -> 0 | BH5: =BG5/Y5 -> #DIV/0!
A6: =B6 -> 46115 | B6: =B5+1 -> 46115 | C6: 89998 | D6: =C6+D5 -> 248252 | E6: 95000 | F6: =E6+F5 -> 285000 | G6: 89991 | I6: =H6+I5 -> 0 | J6: =H6-E6 -> -95000 | K6: =J6+K5 -> -285000 | M6: =L7+M5 -> 0 | N6: =K6/F6 -> -1 | O6: =H6-G6 -> -89991 | P6: =IF(ISERROR(O6/G6),0,O6/G6) -> -1 | Q6: =(I6-D6)/D6 -> -1 | S6: =R6/H6 -> #DIV/0! | T6: 323 | U6: =T6+U5 -> 918 | V6: 340 | W6: =V6+W5 -> 1020 | Y6: =X6+Y5 -> 0 | Z6: =Y6-W6 -> -1020 | AA6: =Y6-U6 -> -918 | AB6: =(Y6-U6)/U6 -> -1 | AC6: =C6/T6 -> 278.63158 | AD6: =E6/V6 -> 279.41176 | AE6: =H6/X6 -> #DIV/0! | AF6: =AE6-AD6 -> #DIV/0! | AH6: 88 | AI6: =AH6+AI5 -> 264 | AJ6: =$AI$1*8 -> 48 | AL6: 0 | AM6: =SUM(AK6:AL6) -> 0 | AN6: =AM6+AN5 -> 0 | AO6: =SUM(AM6)-AH6 -> -88 | AP6: =SUM(AJ6:AL6)*AQ$1 -> 4032 | AQ6: =SUM(AP6,AQ5) -> 12096 | AR6: =IF(ISERROR(AQ6/I6),0,AQ6/I6) -> 0 | AS6: =Y6/AN6 -> #DIV/0! | AU6: =AT6+AU5 -> 0 | AV6: =AU6/Y6 -> #DIV/0! | AX6: =AW6+AX5 -> 0 | AY6: =AX6/Y6 -> #DIV/0! | BA6: =AZ6+BA5 -> 0 | BB6: =BA6/Y6 -> #DIV/0! | BD6: =BC6+BD5 -> 0 | BE6: =BD6/Y6 -> #DIV/0! | BG6: =BF6+BG5 -> 0 | BH6: =BG6/Y6 -> #DIV/0!
A7: =B7 -> 46116 | B7: =B6+1 -> 46116 | C7: 85411 | D7: =C7+D6 -> 333663 | E7: 95000 | F7: =E7+F6 -> 380000 | G7: 100705 | I7: =H7+I6 -> 0 | J7: =H7-E7 -> -95000 | K7: =J7+K6 -> -380000 | M7: =L8+M6 -> 0 | N7: =K7/F7 -> -1 | O7: =H7-G7 -> -100705 | P7: =IF(ISERROR(O7/G7),0,O7/G7) -> -1 | Q7: =(I7-D7)/D7 -> -1 | S7: =R7/H7 -> #DIV/0! | T7: 319 | U7: =T7+U6 -> 1237 | V7: 340 | W7: =V7+W6 -> 1360 | Y7: =X7+Y6 -> 0 | Z7: =Y7-W7 -> -1360 | AA7: =Y7-U7 -> -1237 | AB7: =(Y7-U7)/U7 -> -1 | AC7: =C7/T7 -> 267.74608 | AD7: =E7/V7 -> 279.41176 | AE7: =H7/X7 -> #DIV/0! | AF7: =AE7-AD7 -> #DIV/0! | AH7: 88 | AI7: =AH7+AI6 -> 352 | AJ7: =$AI$1*8 -> 48 | AL7: 0 | AM7: =SUM(AK7:AL7) -> 0 | AN7: =AM7+AN6 -> 0 | AO7: =SUM(AM7)-AH7 -> -88 | AP7: =SUM(AJ7:AL7)*AQ$1 -> 4032 | AQ7: =SUM(AP7,AQ6) -> 16128 | AR7: =IF(ISERROR(AQ7/I7),0,AQ7/I7) -> 0 | AS7: =Y7/AN7 -> #DIV/0! | AU7: =AT7+AU6 -> 0 | AV7: =AU7/Y7 -> #DIV/0! | AX7: =AW7+AX6 -> 0 | AY7: =AX7/Y7 -> #DIV/0! | BA7: =AZ7+BA6 -> 0 | BB7: =BA7/Y7 -> #DIV/0! | BD7: =BC7+BD6 -> 0 | BE7: =BD7/Y7 -> #DIV/0! | BG7: =BF7+BG6 -> 0 | BH7: =BG7/Y7 -> #DIV/0!
A8: =B8 -> 46117 | B8: =B7+1 -> 46117 | C8: 85326 | D8: =C8+D7 -> 418989 | E8: 95000 | F8: =E8+F7 -> 475000 | G8: 92559 | I8: =H8+I7 -> 0 | J8: =H8-E8 -> -95000 | K8: =J8+K7 -> -475000 | M8: =L9+M7 -> 0 | N8: =K8/F8 -> -1 | O8: =H8-G8 -> -92559 | P8: =IF(ISERROR(O8/G8),0,O8/G8) -> -1 | Q8: =(I8-D8)/D8 -> -1 | S8: =R8/H8 -> #DIV/0! | T8: 348 | U8: =T8+U7 -> 1585 | V8: 340 | W8: =V8+W7 -> 1700 | Y8: =X8+Y7 -> 0 | Z8: =Y8-W8 -> -1700 | AA8: =Y8-U8 -> -1585 | AB8: =(Y8-U8)/U8 -> -1 | AC8: =C8/T8 -> 245.18966 | AD8: =E8/V8 -> 279.41176 | AE8: =H8/X8 -> #DIV/0! | AF8: =AE8-AD8 -> #DIV/0! | AH8: 88 | AI8: =AH8+AI7 -> 440 | AJ8: =$AI$1*8 -> 48 | AL8: 0 | AM8: =SUM(AK8:AL8) -> 0 | AN8: =AM8+AN7 -> 0 | AO8: =SUM(AM8)-AH8 -> -88 | AP8: =SUM(AJ8:AL8)*AQ$1 -> 4032 | AQ8: =SUM(AP8,AQ7) -> 20160 | AR8: =IF(ISERROR(AQ8/I8),0,AQ8/I8) -> 0 | AS8: =Y8/AN8 -> #DIV/0! | AU8: =AT8+AU7 -> 0 | AV8: =AU8/Y8 -> #DIV/0! | AX8: =AW8+AX7 -> 0 | AY8: =AX8/Y8 -> #DIV/0! | BA8: =AZ8+BA7 -> 0 | BB8: =BA8/Y8 -> #DIV/0! | BD8: =BC8+BD7 -> 0 | BE8: =BD8/Y8 -> #DIV/0! | BG8: =BF8+BG7 -> 0 | BH8: =BG8/Y8 -> #DIV/0!
A9: =B9 -> 46118 | B9: =B8+1 -> 46118 | C9: 85939 | D9: =C9+D8 -> 504928 | E9: 95000 | F9: =E9+F8 -> 570000 | G9: 82694 | I9: =H9+I8 -> 0 | J9: =H9-E9 -> -95000 | K9: =J9+K8 -> -570000 | M9: =L10+M8 -> 0 | N9: =K9/F9 -> -1 | O9: =H9-G9 -> -82694 | P9: =IF(ISERROR(O9/G9),0,O9/G9) -> -1 | Q9: =(I9-D9)/D9 -> -1 | S9: =R9/H9 -> #DIV/0! | T9: 325 | U9: =T9+U8 -> 1910 | V9: 340 | W9: =V9+W8 -> 2040 | Y9: =X9+Y8 -> 0 | Z9: =Y9-W9 -> -2040 | AA9: =Y9-U9 -> -1910 | AB9: =(Y9-U9)/U9 -> -1 | AC9: =C9/T9 -> 264.42769 | AD9: =E9/V9 -> 279.41176 | AE9: =H9/X9 -> #DIV/0! | AF9: =AE9-AD9 -> #DIV/0! | AH9: 88 | AI9: =AH9+AI8 -> 528 | AJ9: =$AI$1*8 -> 48 | AM9: =SUM(AK9:AL9) -> 0 | AN9: =AM9+AN8 -> 0 | AO9: =SUM(AM9)-AH9 -> -88 | AP9: =SUM(AJ9:AL9)*AQ$1 -> 4032 | AQ9: =SUM(AP9,AQ8) -> 24192 | AR9: =IF(ISERROR(AQ9/I9),0,AQ9/I9) -> 0 | AS9: =Y9/AN9 -> #DIV/0! | AU9: =AT9+AU8 -> 0 | AV9: =AU9/Y9 -> #DIV/0! | AX9: =AW9+AX8 -> 0 | AY9: =AX9/Y9 -> #DIV/0! | BA9: =AZ9+BA8 -> 0 | BB9: =BA9/Y9 -> #DIV/0! | BD9: =BC9+BD8 -> 0 | BE9: =BD9/Y9 -> #DIV/0! | BG9: =BF9+BG8 -> 0 | BH9: =BG9/Y9 -> #DIV/0!
A10: =B10 -> 46119 | B10: =B9+1 -> 46119 | C10: 81209 | D10: =C10+D9 -> 586137 | E10: 95000 | F10: =E10+F9 -> 665000 | G10: 81857 | I10: =H10+I9 -> 0 | J10: =H10-E10 -> -95000 | K10: =J10+K9 -> -665000 | M10: =L11+M9 -> 0 | N10: =K10/F10 -> -1 | O10: =H10-G10 -> -81857 | P10: =IF(ISERROR(O10/G10),0,O10/G10) -> -1 | Q10: =(I10-D10)/D10 -> -1 | S10: =R10/H10 -> #DIV/0! | T10: 306 | U10: =T10+U9 -> 2216 | V10: 340 | W10: =V10+W9 -> 2380 | Y10: =X10+Y9 -> 0 | Z10: =Y10-W10 -> -2380 | AA10: =Y10-U10 -> -2216 | AB10: =(Y10-U10)/U10 -> -1 | AC10: =C10/T10 -> 265.38889 | AD10: =E10/V10 -> 279.41176 | AE10: =H10/X10 -> #DIV/0! | AF10: =AE10-AD10 -> #DIV/0! | AH10: 88 | AI10: =AH10+AI9 -> 616 | AJ10: =$AI$1*8 -> 48 | AL10: 0 | AM10: =SUM(AK10:AL10) -> 0 | AN10: =AM10+AN9 -> 0 | AO10: =SUM(AM10)-AH10 -> -88 | AP10: =SUM(AJ10:AL10)*AQ$1 -> 4032 | AQ10: =SUM(AP10,AQ9) -> 28224 | AR10: =IF(ISERROR(AQ10/I10),0,AQ10/I10) -> 0 | AS10: =Y10/AN10 -> #DIV/0! | AU10: =AT10+AU9 -> 0 | AV10: =AU10/Y10 -> #DIV/0! | AX10: =AW10+AX9 -> 0 | AY10: =AX10/Y10 -> #DIV/0! | BA10: =AZ10+BA9 -> 0 | BB10: =BA10/Y10 -> #DIV/0! | BD10: =BC10+BD9 -> 0 | BE10: =BD10/Y10 -> #DIV/0! | BG10: =BF10+BG9 -> 0 | BH10: =BG10/Y10 -> #DIV/0!
A11: =B11 -> 46120 | B11: =B10+1 -> 46120 | C11: 67228 | D11: =C11+D10 -> 653365 | E11: 95000 | F11: =E11+F10 -> 760000 | G11: 84739 | I11: =H11+I10 -> 0 | J11: =H11-E11 -> -95000 | K11: =J11+K10 -> -760000 | M11: =L12+M10 -> 0 | N11: =K11/F11 -> -1 | O11: =H11-G11 -> -84739 | P11: =IF(ISERROR(O11/G11),0,O11/G11) -> -1 | Q11: =(I11-D11)/D11 -> -1 | S11: =R11/H11 -> #DIV/0! | T11: 266 | U11: =T11+U10 -> 2482 | V11: 340 | W11: =V11+W10 -> 2720 | Y11: =X11+Y10 -> 0 | Z11: =Y11-W11 -> -2720 | AA11: =Y11-U11 -> -2482 | AB11: =(Y11-U11)/U11 -> -1 | AC11: =C11/T11 -> 252.73684 | AD11: =E11/V11 -> 279.41176 | AE11: =H11/X11 -> #DIV/0! | AF11: =AE11-AD11 -> #DIV/0! | AH11: 88 | AI11: =AH11+AI10 -> 704 | AJ11: =$AI$1*8 -> 48 | AL11: 0 | AM11: =SUM(AK11:AL11) -> 0 | AN11: =AM11+AN10 -> 0 | AO11: =SUM(AM11)-AH11 -> -88 | AP11: =SUM(AJ11:AL11)*AQ$1 -> 4032 | AQ11: =SUM(AP11,AQ10) -> 32256 | AR11: =IF(ISERROR(AQ11/I11),0,AQ11/I11) -> 0 | AS11: =Y11/AN11 -> #DIV/0! | AU11: =AT11+AU10 -> 0 | AV11: =AU11/Y11 -> #DIV/0! | AX11: =AW11+AX10 -> 0 | AY11: =AX11/Y11 -> #DIV/0! | BA11: =AZ11+BA10 -> 0 | BB11: =BA11/Y11 -> #DIV/0! | BD11: =BC11+BD10 -> 0 | BE11: =BD11/Y11 -> #DIV/0! | BG11: =BF11+BG10 -> 0 | BH11: =BG11/Y11 -> #DIV/0!
A12: =B12 -> 46121 | B12: =B11+1 -> 46121 | C12: 71444 | D12: =C12+D11 -> 724809 | E12: 95000 | F12: =E12+F11 -> 855000 | G12: 86892 | I12: =H12+I11 -> 0 | J12: =H12-E12 -> -95000 | K12: =J12+K11 -> -855000 | M12: =L13+M11 -> 0 | N12: =K12/F12 -> -1 | O12: =H12-G12 -> -86892 | P12: =IF(ISERROR(O12/G12),0,O12/G12) -> -1 | Q12: =(I12-D12)/D12 -> -1 | S12: =R12/H12 -> #DIV/0! | T12: 282 | U12: =T12+U11 -> 2764 | V12: 340 | W12: =V12+W11 -> 3060 | Y12: =X12+Y11 -> 0 | Z12: =Y12-W12 -> -3060 | AA12: =Y12-U12 -> -2764 | AB12: =(Y12-U12)/U12 -> -1 | AC12: =C12/T12 -> 253.34752 | AD12: =E12/V12 -> 279.41176 | AE12: =H12/X12 -> #DIV/0! | AF12: =AE12-AD12 -> #DIV/0! | AH12: 88 | AI12: =AH12+AI11 -> 792 | AJ12: =$AI$1*8 -> 48 | AL12: 0 | AM12: =SUM(AK12:AL12) -> 0 | AN12: =AM12+AN11 -> 0 | AO12: =SUM(AM12)-AH12 -> -88 | AP12: =SUM(AJ12:AL12)*AQ$1 -> 4032 | AQ12: =SUM(AP12,AQ11) -> 36288 | AR12: =IF(ISERROR(AQ12/I12),0,AQ12/I12) -> 0 | AS12: =Y12/AN12 -> #DIV/0! | AU12: =AT12+AU11 -> 0 | AV12: =AU12/Y12 -> #DIV/0! | AX12: =AW12+AX11 -> 0 | AY12: =AX12/Y12 -> #DIV/0! | BA12: =AZ12+BA11 -> 0 | BB12: =BA12/Y12 -> #DIV/0! | BD12: =BC12+BD11 -> 0 | BE12: =BD12/Y12 -> #DIV/0! | BG12: =BF12+BG11 -> 0 | BH12: =BG12/Y12 -> #DIV/0!
A13: =B13 -> 46122 | B13: =B12+1 -> 46122 | C13: 66534 | D13: =C13+D12 -> 791343 | E13: 95000 | F13: =E13+F12 -> 950000 | G13: 93274 | I13: =H13+I12 -> 0 | J13: =H13-E13 -> -95000 | K13: =J13+K12 -> -950000 | M13: =L14+M12 -> 0 | N13: =K13/F13 -> -1 | O13: =H13-G13 -> -93274 | P13: =IF(ISERROR(O13/G13),0,O13/G13) -> -1 | Q13: =(I13-D13)/D13 -> -1 | S13: =R13/H13 -> #DIV/0! | T13: 267 | U13: =T13+U12 -> 3031 | V13: 340 | W13: =V13+W12 -> 3400 | Y13: =X13+Y12 -> 0 | Z13: =Y13-W13 -> -3400 | AA13: =Y13-U13 -> -3031 | AB13: =(Y13-U13)/U13 -> -1 | AC13: =C13/T13 -> 249.19101 | AD13: =E13/V13 -> 279.41176 | AE13: =H13/X13 -> #DIV/0! | AF13: =AE13-AD13 -> #DIV/0! | AH13: 88 | AI13: =AH13+AI12 -> 880 | AJ13: =$AI$1*8 -> 48 | AL13: 0 | AM13: =SUM(AK13:AL13) -> 0 | AN13: =AM13+AN12 -> 0 | AO13: =SUM(AM13)-AH13 -> -88 | AP13: =SUM(AJ13:AL13)*AQ$1 -> 4032 | AQ13: =SUM(AP13,AQ12) -> 40320 | AR13: =IF(ISERROR(AQ13/I13),0,AQ13/I13) -> 0 | AS13: =Y13/AN13 -> #DIV/0! | AU13: =AT13+AU12 -> 0 | AV13: =AU13/Y13 -> #DIV/0! | AX13: =AW13+AX12 -> 0 | AY13: =AX13/Y13 -> #DIV/0! | BA13: =AZ13+BA12 -> 0 | BB13: =BA13/Y13 -> #DIV/0! | BD13: =BC13+BD12 -> 0 | BE13: =BD13/Y13 -> #DIV/0! | BG13: =BF13+BG12 -> 0 | BH13: =BG13/Y13 -> #DIV/0!
A14: =B14 -> 46123 | B14: =B13+1 -> 46123 | C14: 91925 | D14: =C14+D13 -> 883268 | E14: 95000 | F14: =E14+F13 -> 1045000 | G14: 100705 | I14: =H14+I13 -> 0 | J14: =H14-E14 -> -95000 | K14: =J14+K13 -> -1045000 | M14: =L15+M13 -> 0 | N14: =K14/F14 -> -1 | O14: =H14-G14 -> -100705 | P14: =IF(ISERROR(O14/G14),0,O14/G14) -> -1 | Q14: =(I14-D14)/D14 -> -1 | S14: =R14/H14 -> #DIV/0! | T14: 332 | U14: =T14+U13 -> 3363 | V14: 340 | W14: =V14+W13 -> 3740 | Y14: =X14+Y13 -> 0 | Z14: =Y14-W14 -> -3740 | AA14: =Y14-U14 -> -3363 | AB14: =(Y14-U14)/U14 -> -1 | AC14: =C14/T14 -> 276.88253 | AD14: =E14/V14 -> 279.41176 | AE14: =H14/X14 -> #DIV/0! | AF14: =AE14-AD14 -> #DIV/0! | AH14: 88 | AI14: =AH14+AI13 -> 968 | AJ14: =$AI$1*8 -> 48 | AL14: 0 | AM14: =SUM(AK14:AL14) -> 0 | AN14: =AM14+AN13 -> 0 | AO14: =SUM(AM14)-AH14 -> -88 | AP14: =SUM(AJ14:AL14)*AQ$1 -> 4032 | AQ14: =SUM(AP14,AQ13) -> 44352 | AR14: =IF(ISERROR(AQ14/I14),0,AQ14/I14) -> 0 | AS14: =Y14/AN14 -> #DIV/0! | AU14: =AT14+AU13 -> 0 | AV14: =AU14/Y14 -> #DIV/0! | AX14: =AW14+AX13 -> 0 | AY14: =AX14/Y14 -> #DIV/0! | BA14: =AZ14+BA13 -> 0 | BB14: =BA14/Y14 -> #DIV/0! | BD14: =BC14+BD13 -> 0 | BE14: =BD14/Y14 -> #DIV/0! | BG14: =BF14+BG13 -> 0 | BH14: =BG14/Y14 -> #DIV/0!
A15: =B15 -> 46124 | B15: =B14+1 -> 46124 | C15: 96973 | D15: =C15+D14 -> 980241 | E15: 95000 | F15: =E15+F14 -> 1140000 | G15: 89463 | I15: =H15+I14 -> 0 | J15: =H15-E15 -> -95000 | K15: =J15+K14 -> -1140000 | M15: =L16+M14 -> 0 | N15: =K15/F15 -> -1 | O15: =H15-G15 -> -89463 | P15: =IF(ISERROR(O15/G15),0,O15/G15) -> -1 | Q15: =(I15-D15)/D15 -> -1 | S15: =R15/H15 -> #DIV/0! | T15: 375 | U15: =T15+U14 -> 3738 | V15: 340 | W15: =V15+W14 -> 4080 | Y15: =X15+Y14 -> 0 | Z15: =Y15-W15 -> -4080 | AA15: =Y15-U15 -> -3738 | AB15: =(Y15-U15)/U15 -> -1 | AC15: =C15/T15 -> 258.59467 | AD15: =E15/V15 -> 279.41176 | AE15: =H15/X15 -> #DIV/0! | AF15: =AE15-AD15 -> #DIV/0! | AH15: 88 | AI15: =AH15+AI14 -> 1056 | AJ15: =$AI$1*8 -> 48 | AL15: 0 | AM15: =SUM(AK15:AL15) -> 0 | AN15: =AM15+AN14 -> 0 | AO15: =SUM(AM15)-AH15 -> -88 | AP15: =SUM(AJ15:AL15)*AQ$1 -> 4032 | AQ15: =SUM(AP15,AQ14) -> 48384 | AR15: =IF(ISERROR(AQ15/I15),0,AQ15/I15) -> 0 | AS15: =Y15/AN15 -> #DIV/0! | AU15: =AT15+AU14 -> 0 | AV15: =AU15/Y15 -> #DIV/0! | AX15: =AW15+AX14 -> 0 | AY15: =AX15/Y15 -> #DIV/0! | BA15: =AZ15+BA14 -> 0 | BB15: =BA15/Y15 -> #DIV/0! | BD15: =BC15+BD14 -> 0 | BE15: =BD15/Y15 -> #DIV/0! | BG15: =BF15+BG14 -> 0 | BH15: =BG15/Y15 -> #DIV/0!
A16: =B16 -> 46125 | B16: =B15+1 -> 46125 | C16: 91298 | D16: =C16+D15 -> 1071539 | E16: 95000 | F16: =E16+F15 -> 1235000 | G16: 84722 | I16: =H16+I15 -> 0 | J16: =H16-E16 -> -95000 | K16: =J16+K15 -> -1235000 | M16: =L17+M15 -> 0 | N16: =K16/F16 -> -1 | O16: =H16-G16 -> -84722 | P16: =IF(ISERROR(O16/G16),0,O16/G16) -> -1 | Q16: =(I16-D16)/D16 -> -1 | S16: =R16/H16 -> #DIV/0! | T16: 327 | U16: =T16+U15 -> 4065 | V16: 340 | W16: =V16+W15 -> 4420 | Y16: =X16+Y15 -> 0 | Z16: =Y16-W16 -> -4420 | AA16: =Y16-U16 -> -4065 | AB16: =(Y16-U16)/U16 -> -1 | AC16: =C16/T16 -> 279.19878 | AD16: =E16/V16 -> 279.41176 | AE16: =H16/X16 -> #DIV/0! | AF16: =AE16-AD16 -> #DIV/0! | AH16: 88 | AI16: =AH16+AI15 -> 1144 | AJ16: =$AI$1*8 -> 48 | AL16: 0 | AM16: =SUM(AK16:AL16) -> 0 | AN16: =AM16+AN15 -> 0 | AO16: =SUM(AM16)-AH16 -> -88 | AP16: =SUM(AJ16:AL16)*AQ$1 -> 4032 | AQ16: =SUM(AP16,AQ15) -> 52416 | AR16: =IF(ISERROR(AQ16/I16),0,AQ16/I16) -> 0 | AS16: =Y16/AN16 -> #DIV/0! | AU16: =AT16+AU15 -> 0 | AV16: =AU16/Y16 -> #DIV/0! | AX16: =AW16+AX15 -> 0 | AY16: =AX16/Y16 -> #DIV/0! | BA16: =AZ16+BA15 -> 0 | BB16: =BA16/Y16 -> #DIV/0! | BD16: =BC16+BD15 -> 0 | BE16: =BD16/Y16 -> #DIV/0! | BG16: =BF16+BG15 -> 0 | BH16: =BG16/Y16 -> #DIV/0!
A17: =B17 -> 46126 | B17: =B16+1 -> 46126 | C17: 98688 | D17: =C17+D16 -> 1170227 | E17: 95000 | F17: =E17+F16 -> 1330000 | G17: 81857 | I17: =H17+I16 -> 0 | J17: =H17-E17 -> -95000 | K17: =J17+K16 -> -1330000 | M17: =L18+M16 -> 0 | N17: =K17/F17 -> -1 | O17: =H17-G17 -> -81857 | P17: =IF(ISERROR(O17/G17),0,O17/G17) -> -1 | Q17: =(I17-D17)/D17 -> -1 | S17: =R17/H17 -> #DIV/0! | T17: 379 | U17: =T17+U16 -> 4444 | V17: 340 | W17: =V17+W16 -> 4760 | Y17: =X17+Y16 -> 0 | Z17: =Y17-W17 -> -4760 | AA17: =Y17-U17 -> -4444 | AB17: =(Y17-U17)/U17 -> -1 | AC17: =C17/T17 -> 260.3905 | AD17: =E17/V17 -> 279.41176 | AE17: =H17/X17 -> #DIV/0! | AF17: =AE17-AD17 -> #DIV/0! | AH17: 88 | AI17: =AH17+AI16 -> 1232 | AJ17: =$AI$1*8 -> 48 | AL17: 0 | AM17: =SUM(AK17:AL17) -> 0 | AN17: =AM17+AN16 -> 0 | AO17: =SUM(AM17)-AH17 -> -88 | AP17: =SUM(AJ17:AL17)*AQ$1 -> 4032 | AQ17: =SUM(AP17,AQ16) -> 56448 | AR17: =IF(ISERROR(AQ17/I17),0,AQ17/I17) -> 0 | AS17: =Y17/AN17 -> #DIV/0! | AU17: =AT17+AU16 -> 0 | AV17: =AU17/Y17 -> #DIV/0! | AX17: =AW17+AX16 -> 0 | AY17: =AX17/Y17 -> #DIV/0! | BA17: =AZ17+BA16 -> 0 | BB17: =BA17/Y17 -> #DIV/0! | BD17: =BC17+BD16 -> 0 | BE17: =BD17/Y17 -> #DIV/0! | BG17: =BF17+BG16 -> 0 | BH17: =BG17/Y17 -> #DIV/0!
A18: =B18 -> 46127 | B18: =B17+1 -> 46127 | C18: 89841 | D18: =C18+D17 -> 1260068 | E18: 95000 | F18: =E18+F17 -> 1425000 | G18: 84739 | I18: =H18+I17 -> 0 | J18: =H18-E18 -> -95000 | K18: =J18+K17 -> -1425000 | M18: =L19+M17 -> 0 | N18: =K18/F18 -> -1 | O18: =H18-G18 -> -84739 | P18: =IF(ISERROR(O18/G18),0,O18/G18) -> -1 | Q18: =(I18-D18)/D18 -> -1 | S18: =R18/H18 -> #DIV/0! | T18: 328 | U18: =T18+U17 -> 4772 | V18: 340 | W18: =V18+W17 -> 5100 | Y18: =X18+Y17 -> 0 | Z18: =Y18-W18 -> -5100 | AA18: =Y18-U18 -> -4772 | AB18: =(Y18-U18)/U18 -> -1 | AC18: =C18/T18 -> 273.90549 | AD18: =E18/V18 -> 279.41176 | AE18: =H18/X18 -> #DIV/0! | AF18: =AE18-AD18 -> #DIV/0! | AH18: 88 | AI18: =AH18+AI17 -> 1320 | AJ18: =$AI$1*8 -> 48 | AL18: 0 | AM18: =SUM(AK18:AL18) -> 0 | AN18: =AM18+AN17 -> 0 | AO18: =SUM(AM18)-AH18 -> -88 | AP18: =SUM(AJ18:AL18)*AQ$1 -> 4032 | AQ18: =SUM(AP18,AQ17) -> 60480 | AR18: =IF(ISERROR(AQ18/I18),0,AQ18/I18) -> 0 | AS18: =Y18/AN18 -> #DIV/0! | AU18: =AT18+AU17 -> 0 | AV18: =AU18/Y18 -> #DIV/0! | AX18: =AW18+AX17 -> 0 | AY18: =AX18/Y18 -> #DIV/0! | BA18: =AZ18+BA17 -> 0 | BB18: =BA18/Y18 -> #DIV/0! | BD18: =BC18+BD17 -> 0 | BE18: =BD18/Y18 -> #DIV/0! | BG18: =BF18+BG17 -> 0 | BH18: =BG18/Y18 -> #DIV/0!
A19: =B19 -> 46128 | B19: =B18+1 -> 46128 | C19: 99492 | D19: =C19+D18 -> 1359560 | E19: 95000 | F19: =E19+F18 -> 1520000 | G19: 86892 | I19: =H19+I18 -> 0 | J19: =H19-E19 -> -95000 | K19: =J19+K18 -> -1520000 | M19: =L20+M18 -> 0 | N19: =K19/F19 -> -1 | O19: =H19-G19 -> -86892 | P19: =IF(ISERROR(O19/G19),0,O19/G19) -> -1 | Q19: =(I19-D19)/D19 -> -1 | S19: =R19/H19 -> #DIV/0! | T19: 339 | U19: =T19+U18 -> 5111 | V19: 340 | W19: =V19+W18 -> 5440 | Y19: =X19+Y18 -> 0 | Z19: =Y19-W19 -> -5440 | AA19: =Y19-U19 -> -5111 | AB19: =(Y19-U19)/U19 -> -1 | AC19: =C19/T19 -> 293.48673 | AD19: =E19/V19 -> 279.41176 | AE19: =H19/X19 -> #DIV/0! | AF19: =AE19-AD19 -> #DIV/0! | AH19: 88 | AI19: =AH19+AI18 -> 1408 | AJ19: =$AI$1*8 -> 48 | AL19: 0 | AM19: =SUM(AK19:AL19) -> 0 | AN19: =AM19+AN18 -> 0 | AO19: =SUM(AM19)-AH19 -> -88 | AP19: =SUM(AJ19:AL19)*AQ$1 -> 4032 | AQ19: =SUM(AP19,AQ18) -> 64512 | AR19: =IF(ISERROR(AQ19/I19),0,AQ19/I19) -> 0 | AS19: =Y19/AN19 -> #DIV/0! | AU19: =AT19+AU18 -> 0 | AV19: =AU19/Y19 -> #DIV/0! | AX19: =AW19+AX18 -> 0 | AY19: =AX19/Y19 -> #DIV/0! | BA19: =AZ19+BA18 -> 0 | BB19: =BA19/Y19 -> #DIV/0! | BD19: =BC19+BD18 -> 0 | BE19: =BD19/Y19 -> #DIV/0! | BG19: =BF19+BG18 -> 0 | BH19: =BG19/Y19 -> #DIV/0!
A20: =B20 -> 46129 | B20: =B19+1 -> 46129 | C20: 92429 | D20: =C20+D19 -> 1451989 | E20: 95000 | F20: =E20+F19 -> 1615000 | G20: 93274 | I20: =H20+I19 -> 0 | J20: =H20-E20 -> -95000 | K20: =J20+K19 -> -1615000 | M20: =L21+M19 -> 0 | N20: =K20/F20 -> -1 | O20: =H20-G20 -> -93274 | P20: =IF(ISERROR(O20/G20),0,O20/G20) -> -1 | Q20: =(I20-D20)/D20 -> -1 | S20: =R20/H20 -> #DIV/0! | T20: 297 | U20: =T20+U19 -> 5408 | V20: 340 | W20: =V20+W19 -> 5780 | Y20: =X20+Y19 -> 0 | Z20: =Y20-W20 -> -5780 | AA20: =Y20-U20 -> -5408 | AB20: =(Y20-U20)/U20 -> -1 | AC20: =C20/T20 -> 311.20875 | AD20: =E20/V20 -> 279.41176 | AE20: =H20/X20 -> #DIV/0! | AF20: =AE20-AD20 -> #DIV/0! | AH20: 88 | AI20: =AH20+AI19 -> 1496 | AJ20: =$AI$1*8 -> 48 | AL20: 0 | AM20: =SUM(AK20:AL20) -> 0 | AN20: =AM20+AN19 -> 0 | AO20: =SUM(AM20)-AH20 -> -88 | AP20: =SUM(AJ20:AL20)*AQ$1 -> 4032 | AQ20: =SUM(AP20,AQ19) -> 68544 | AR20: =IF(ISERROR(AQ20/I20),0,AQ20/I20) -> 0 | AS20: =Y20/AN20 -> #DIV/0! | AU20: =AT20+AU19 -> 0 | AV20: =AU20/Y20 -> #DIV/0! | AX20: =AW20+AX19 -> 0 | AY20: =AX20/Y20 -> #DIV/0! | BA20: =AZ20+BA19 -> 0 | BB20: =BA20/Y20 -> #DIV/0! | BD20: =BC20+BD19 -> 0 | BE20: =BD20/Y20 -> #DIV/0! | BG20: =BF20+BG19 -> 0 | BH20: =BG20/Y20 -> #DIV/0!
A21: =B21 -> 46130 | B21: =B20+1 -> 46130 | C21: 71996 | D21: =C21+D20 -> 1523985 | E21: 95000 | F21: =E21+F20 -> 1710000 | G21: 100705 | I21: =H21+I20 -> 0 | J21: =H21-E21 -> -95000 | K21: =J21+K20 -> -1710000 | M21: =L22+M20 -> 0 | N21: =K21/F21 -> -1 | O21: =H21-G21 -> -100705 | P21: =IF(ISERROR(O21/G21),0,O21/G21) -> -1 | Q21: =(I21-D21)/D21 -> -1 | S21: =R21/H21 -> #DIV/0! | T21: 291 | U21: =T21+U20 -> 5699 | V21: 340 | W21: =V21+W20 -> 6120 | Y21: =X21+Y20 -> 0 | Z21: =Y21-W21 -> -6120 | AA21: =Y21-U21 -> -5699 | AB21: =(Y21-U21)/U21 -> -1 | AC21: =C21/T21 -> 247.40893 | AD21: =E21/V21 -> 279.41176 | AE21: =H21/X21 -> #DIV/0! | AF21: =AE21-AD21 -> #DIV/0! | AH21: 88 | AI21: =AH21+AI20 -> 1584 | AJ21: =$AI$1*8 -> 48 | AL21: 0 | AM21: =SUM(AK21:AL21) -> 0 | AN21: =AM21+AN20 -> 0 | AO21: =SUM(AM21)-AH21 -> -88 | AP21: =SUM(AJ21:AL21)*AQ$1 -> 4032 | AQ21: =SUM(AP21,AQ20) -> 72576 | AR21: =IF(ISERROR(AQ21/I21),0,AQ21/I21) -> 0 | AS21: =Y21/AN21 -> #DIV/0! | AU21: =AT21+AU20 -> 0 | AV21: =AU21/Y21 -> #DIV/0! | AX21: =AW21+AX20 -> 0 | AY21: =AX21/Y21 -> #DIV/0! | BA21: =AZ21+BA20 -> 0 | BB21: =BA21/Y21 -> #DIV/0! | BD21: =BC21+BD20 -> 0 | BE21: =BD21/Y21 -> #DIV/0! | BG21: =BF21+BG20 -> 0 | BH21: =BG21/Y21 -> #DIV/0!
... A33: =B33 -> 46142 | B33: =B32+1 -> 46142 | C33: 98658 | D33: =C33+D32 -> 2643841 | E33: 95000 | F33: =E33+F32 -> 2850000 | G33: 86892 | I33: =H33+I32 -> 0 | J33: =H33-E33 -> -95000 | K33: =J33+K32 -> -2850000 | M33: =L34+M32 -> 0 | N33: =K33/F33 -> -1 | O33: =H33-G33 -> -86892 | P33: =IF(ISERROR(O33/G33),0,O33/G33) -> -1 | Q33: =(I33-D33)/D33 -> -1 | S33: =R33/H33 -> #DIV/0! | T33: 345 | U33: =T33+U32 -> 9932 | V33: 340 | W33: =V33+W32 -> 10200 | Y33: =X33+Y32 -> 0 | Z33: =Y33-W33 -> -10200 | AA33: =Y33-U33 -> -9932 | AB33: =(Y33-U33)/U33 -> -1 | AC33: =C33/T33 -> 285.96522 | AD33: =E33/V33 -> 279.41176 | AE33: =H33/X33 -> #DIV/0! | AF33: =AE33-AD33 -> #DIV/0! | AH33: 88 | AI33: =AH33+AI32 -> 2640 | AJ33: =$AI$1*8 -> 48 | AL33: 0 | AM33: =SUM(AK33:AL33) -> 0 | AN33: =AM33+AN32 -> 0 | AO33: =SUM(AM33)-AH33 -> -88 | AP33: =SUM(AJ33:AL33)*AQ$1 -> 4032 | AQ33: =SUM(AP33,AQ32) -> 120960 | AR33: =IF(ISERROR(AQ33/I33),0,AQ33/I33) -> 0 | AS33: =Y33/AN33 -> #DIV/0! | AU33: =AT33+AU32 -> 0 | AV33: =AU33/Y33 -> #DIV/0! | AX33: =AW33+AX32 -> 0 | AY33: =AX33/Y33 -> #DIV/0! | BA33: =AZ33+BA32 -> 0 | BB33: =BA33/Y33 -> #DIV/0! | BD33: =BC33+BD32 -> 0 | BE33: =BD33/Y33 -> #DIV/0! | BG33: =BF33+BG32 -> 0 | BH33: =BG33/Y33 -> #DIV/0!
A34: =B34 -> 46143 | B34: =B33+1 -> 46143 | D34: =C34+D33 -> 2643841 | F34: =E34+F33 -> 2850000 | I34: =H34+I33 -> 0 | J34: =H34-E34 -> 0 | K34: =J34+K33 -> -2850000 | M34: =L35+M33 -> 0 | N34: =K34/F34 -> -1 | O34: =H34-G34 -> 0 | P34: =IF(ISERROR(O34/G34),0,O34/G34) -> 0 | Q34: =(I34-D34)/D34 -> -1 | S34: =R34/H34 -> #DIV/0! | U34: =T34+U33 -> 9932 | W34: =V34+W33 -> 10200 | Y34: =X34+Y33 -> 0 | Z34: =Y34-W34 -> -10200 | AA34: =Y34-U34 -> -9932 | AB34: =(Y34-U34)/U34 -> -1 | AC34: =C34/T34 -> #DIV/0! | AD34: =E34/V34 -> #DIV/0! | AE34: =H34/X34 -> #DIV/0! | AF34: =AE34-AD34 -> #DIV/0! | AI34: =AH34+AI33 -> 2640 | AJ34: =$AI$1*8 -> 48 | AL34: 0 | AM34: =SUM(AK34:AL34) -> 0 | AN34: =AM34+AN33 -> 0 | AO34: =SUM(AM34)-AH34 -> 0 | AP34: =SUM(AJ34:AL34)*AQ$1 -> 4032 | AQ34: =SUM(AP34,AQ33) -> 124992 | AR34: =IF(ISERROR(AQ34/I34),0,AQ34/I34) -> 0 | AS34: =Y34/AN34 -> #DIV/0! | AU34: =AT34+AU33 -> 0 | AV34: =AU34/Y34 -> #DIV/0! | AX34: =AW34+AX33 -> 0 | AY34: =AX34/Y34 -> #DIV/0! | BA34: =AZ34+BA33 -> 0 | BB34: =BA34/Y34 -> #DIV/0! | BD34: =BC34+BD33 -> 0 | BE34: =BD34/Y34 -> #DIV/0! | BG34: =BF34+BG33 -> 0 | BH34: =BG34/Y34 -> #DIV/0!
A35: Total | C35: =SUM(C4:C34) -> 2643841 | D35: =D34 -> 2643841 | E35: =SUM(E4:E34) -> 2850000 | F35: =F34 -> 2850000 | G35: =SUM(G4:G34) -> 2655101 | H35: =SUM(H4:H34) -> 0 | J35: =SUM(J4:J34) -> -2850000 | L35: =SUM(L5:L34) -> 0 | N35: =H35/F35 -> 0 | O35: =SUM(O4:O34) -> -2655101 | R35: =SUM(R4:R34) -> 0 | S35: =R35/H35 -> #DIV/0! | T35: =SUM(T4:T34) -> 9932 | U35: =U34 -> 9932 | V35: =SUM(V4:V34) -> 10200 | W35: =W34 -> 10200 | X35: =SUM(X4:X34) -> 0 | Y35: =Y34 -> 0 | Z35: =SUM(Z4:Z34) -> -168300 | AA35: =AA34 -> -9932 | AB35: =AB34 -> -1 | AC35: =C35/T35 -> 266.19422 | AD35: =E35/V35 -> 279.41176 | AE35: =H35/X35 -> #DIV/0! | AF35: =AE35-AD35 -> #DIV/0! | AG35: =SUM(AG4:AG34) -> 0 | AH35: =SUM(AH4:AH34) -> 2640 | AI35: =AI34 -> 2640 | AJ35: =SUM(AJ4:AJ34) -> 1488 | AK35: =SUM(AK4:AK34) -> 0 | AL35: =SUM(AL4:AL34) -> 0 | AM35: =SUM(AM4:AM34) -> 0 | AN35: =AN34 -> 0 | AO35: =SUM(AK35:AL35)-AH35 -> -2640 | AP35: =SUM(AP4:AP34) -> 124992 | AR35: =AP35/H35 -> #DIV/0! | AS35: =Y35/AN35 -> #DIV/0! | AT35: =SUM(AT4:AT34) -> 0 | AU35: =AU34 -> 0 | AV35: =AU35/Y35 -> #DIV/0! | AW35: =SUM(AW4:AW34) -> 0 | AX35: =AX34 -> 0 | AY35: =AX35/Y35 -> #DIV/0! | AZ35: =SUM(AZ4:AZ34) -> 0 | BA35: =BA34 -> 0 | BB35: =BA35/Y35 -> #DIV/0! | BC35: =SUM(BC4:BC34) -> 0 | BD35: =BD34 -> 0 | BE35: =BD35/Y35 -> #DIV/0! | BF35: =SUM(BF4:BF34) -> 0 | BG35: =BG34 -> 0 | BH35: =BG35/Y35 -> #DIV/0!

Sheet  GSI สาขาที่มี Delivery
A2: GSI Ratings
A3: Store Name: | B3: Grand Diamond
A4: Date | B4: GSI | C4: OSAT | E4: Google Review | G4: Delivery Rating | I4: Check By
A5: 46113 | B5: =D5+F5+H5 -> 0 | D5: =C5*50% -> 0 | F5: =E5*15% -> 0 | H5: =G5*35% -> 0
A6: =A5+1 -> 46114 | B6: =D6+F6+H6 -> 0 | D6: =C6*50% -> 0 | F6: =E6*15% -> 0 | H6: =G6*35% -> 0
A7: =A6+1 -> 46115 | B7: =D7+F7+H7 -> 0 | D7: =C7*50% -> 0 | F7: =E7*15% -> 0 | H7: =G7*35% -> 0
A8: =A7+1 -> 46116 | B8: =D8+F8+H8 -> 0 | D8: =C8*50% -> 0 | F8: =E8*15% -> 0 | H8: =G8*35% -> 0
A9: =A8+1 -> 46117 | B9: =D9+F9+H9 -> 0 | D9: =C9*50% -> 0 | F9: =E9*15% -> 0 | H9: =G9*35% -> 0
A10: =A9+1 -> 46118 | B10: =D10+F10+H10 -> 0 | D10: =C10*50% -> 0 | F10: =E10*15% -> 0 | H10: =G10*35% -> 0
A11: =A10+1 -> 46119 | B11: =D11+F11+H11 -> 0 | D11: =C11*50% -> 0 | F11: =E11*15% -> 0 | H11: =G11*35% -> 0
A12: =A11+1 -> 46120 | B12: =D12+F12+H12 -> 0 | D12: =C12*50% -> 0 | F12: =E12*15% -> 0 | H12: =G12*35% -> 0
A13: =A12+1 -> 46121 | B13: =D13+F13+H13 -> 0 | D13: =C13*50% -> 0 | F13: =E13*15% -> 0 | H13: =G13*35% -> 0
A14: =A13+1 -> 46122 | B14: =D14+F14+H14 -> 0 | D14: =C14*50% -> 0 | F14: =E14*15% -> 0 | H14: =G14*35% -> 0
A15: =A14+1 -> 46123 | B15: =D15+F15+H15 -> 0 | D15: =C15*50% -> 0 | F15: =E15*15% -> 0 | H15: =G15*35% -> 0
A16: =A15+1 -> 46124 | B16: =D16+F16+H16 -> 0 | D16: =C16*50% -> 0 | F16: =E16*15% -> 0 | H16: =G16*35% -> 0
A17: =A16+1 -> 46125 | B17: =D17+F17+H17 -> 0 | D17: =C17*50% -> 0 | F17: =E17*15% -> 0 | H17: =G17*35% -> 0
... A35: =A34+1 -> 46143 | B35: =D35+F35+H35 -> 0 | D35: =C35*50% -> 0 | F35: =E35*15% -> 0 | H35: =G35*35% -> 0
A36: Average Rating | B36: =D36+F36+H36 -> #DIV/0! | C36: =AVERAGE(C5:C35) -> #DIV/0! | D36: =C36*50% -> #DIV/0! | E36: =AVERAGE(E5:E35) -> #DIV/0! | F36: =E36*15% -> #DIV/0! | G36: =AVERAGE(G5:G35) -> #DIV/0! | H36: =G36*35% -> #DIV/0!

Sheet COL Daily
A1: Labour control sheet
A2: Month : | C2: 45901 | D2: Budget | E2: 0.14
A4: Avg. per hour | E4: 50 | F4: ค่ารถ Close shift | G4: 50
A5: Date | B5: Day | C5: Fix cost (Full time) | D5: Total Hrs (Part Time) | E5: Cost | F5: จำนวนคนปิดร้าน | G5: Close shift | H5: COL(day) | I5: Accum. COL | K5: Sales(day) | L5: Sales MTD | M5: % Daily | N5: MTD % total | O5: VAR
A6: =C2 -> 45901 | B6: =A6 -> 45901 | C6: 4754.8387 | D6: ='Sales Management Sheet'!AK4 -> 0 | E6: =D6*$E$4 -> 0 | F6: 4 | G6: =F6*$G$4 -> 200 | H6: =C6+E6+G6 -> 4954.8387 | I6: =H6 -> 4954.8387 | K6: ='Sales Management Sheet'!H4 -> 0 | L6: =K6 -> 0 | M6: =SUM(H6/K6) -> #DIV/0! | N6: =SUM(I6/L6) -> #DIV/0! | O6: =N6-$E$2 -> #DIV/0!
A7: =A6+1 -> 45902 | B7: =A7 -> 45902 | C7: 4754.8387 | D7: ='Sales Management Sheet'!AK5 -> 0 | E7: =D7*$E$4 -> 0 | F7: 2 | G7: =F7*$G$4 -> 100 | H7: =C7+E7+G7 -> 4854.8387 | I7: =SUM(I6+H7) -> 9809.6774 | K7: ='Sales Management Sheet'!H5 -> 0 | L7: =SUM(L6+K7) -> 0 | M7: =SUM(H7/K7) -> #DIV/0! | N7: =SUM(I7/L7) -> #DIV/0! | O7: =N7-$E$2 -> #DIV/0!
A8: =A7+1 -> 45903 | B8: =A8 -> 45903 | C8: 4754.8387 | D8: ='Sales Management Sheet'!AK6 -> 0 | E8: =D8*$E$4 -> 0 | F8: 3 | G8: =F8*$G$4 -> 150 | H8: =C8+E8+G8 -> 4904.8387 | I8: =SUM(I7+H8) -> 14714.516 | K8: ='Sales Management Sheet'!H6 -> 0 | L8: =SUM(L7+K8) -> 0 | M8: =SUM(H8/K8) -> #DIV/0! | N8: =SUM(I8/L8) -> #DIV/0! | O8: =N8-$E$2 -> #DIV/0!
A9: =A8+1 -> 45904 | B9: =A9 -> 45904 | C9: 4754.8387 | D9: ='Sales Management Sheet'!AK7 -> 0 | E9: =D9*$E$4 -> 0 | F9: 3 | G9: =F9*$G$4 -> 150 | H9: =C9+E9+G9 -> 4904.8387 | I9: =SUM(I8+H9) -> 19619.355 | K9: ='Sales Management Sheet'!H7 -> 0 | L9: =SUM(L8+K9) -> 0 | M9: =SUM(H9/K9) -> #DIV/0! | N9: =SUM(I9/L9) -> #DIV/0! | O9: =N9-$E$2 -> #DIV/0!
A10: =A9+1 -> 45905 | B10: =A10 -> 45905 | C10: 4754.8387 | D10: ='Sales Management Sheet'!AK8 -> 0 | E10: =D10*$E$4 -> 0 | F10: 3 | G10: =F10*$G$4 -> 150 | H10: =C10+E10+G10 -> 4904.8387 | I10: =SUM(I9+H10) -> 24524.194 | K10: ='Sales Management Sheet'!H8 -> 0 | L10: =SUM(L9+K10) -> 0 | M10: =SUM(H10/K10) -> #DIV/0! | N10: =SUM(I10/L10) -> #DIV/0! | O10: =N10-$E$2 -> #DIV/0!
A11: =A10+1 -> 45906 | B11: =A11 -> 45906 | C11: 4754.8387 | D11: ='Sales Management Sheet'!AK9 -> 0 | E11: =D11*$E$4 -> 0 | F11: 2 | G11: =F11*$G$4 -> 100 | H11: =C11+E11+G11 -> 4854.8387 | I11: =SUM(I10+H11) -> 29379.032 | K11: ='Sales Management Sheet'!H9 -> 0 | L11: =SUM(L10+K11) -> 0 | M11: =SUM(H11/K11) -> #DIV/0! | N11: =SUM(I11/L11) -> #DIV/0! | O11: =N11-$E$2 -> #DIV/0!
A12: =A11+1 -> 45907 | B12: =A12 -> 45907 | C12: 4754.8387 | D12: ='Sales Management Sheet'!AK10 -> 0 | E12: =D12*$E$4 -> 0 | F12: 2 | G12: =F12*$G$4 -> 100 | H12: =C12+E12+G12 -> 4854.8387 | I12: =SUM(I11+H12) -> 34233.871 | K12: ='Sales Management Sheet'!H10 -> 0 | L12: =SUM(L11+K12) -> 0 | M12: =SUM(H12/K12) -> #DIV/0! | N12: =SUM(I12/L12) -> #DIV/0! | O12: =N12-$E$2 -> #DIV/0!
A13: =A12+1 -> 45908 | B13: =A13 -> 45908 | C13: 4754.8387 | D13: ='Sales Management Sheet'!AK11 -> 0 | E13: =D13*$E$4 -> 0 | F13: 4 | G13: =F13*$G$4 -> 200 | H13: =C13+E13+G13 -> 4954.8387 | I13: =SUM(I12+H13) -> 39188.71 | K13: ='Sales Management Sheet'!H11 -> 0 | L13: =SUM(L12+K13) -> 0 | M13: =SUM(H13/K13) -> #DIV/0! | N13: =SUM(I13/L13) -> #DIV/0! | O13: =N13-$E$2 -> #DIV/0!
A14: =A13+1 -> 45909 | B14: =A14 -> 45909 | C14: 4754.8387 | D14: ='Sales Management Sheet'!AK12 -> 0 | E14: =D14*$E$4 -> 0 | F14: 3 | G14: =F14*$G$4 -> 150 | H14: =C14+E14+G14 -> 4904.8387 | I14: =SUM(I13+H14) -> 44093.548 | K14: ='Sales Management Sheet'!H12 -> 0 | L14: =SUM(L13+K14) -> 0 | M14: =SUM(H14/K14) -> #DIV/0! | N14: =SUM(I14/L14) -> #DIV/0! | O14: =N14-$E$2 -> #DIV/0!
A15: =A14+1 -> 45910 | B15: =A15 -> 45910 | C15: 4754.8387 | D15: ='Sales Management Sheet'!AK13 -> 0 | E15: =D15*$E$4 -> 0 | F15: 3 | G15: =F15*$G$4 -> 150 | H15: =C15+E15+G15 -> 4904.8387 | I15: =SUM(I14+H15) -> 48998.387 | K15: ='Sales Management Sheet'!H13 -> 0 | L15: =SUM(L14+K15) -> 0 | M15: =SUM(H15/K15) -> #DIV/0! | N15: =SUM(I15/L15) -> #DIV/0! | O15: =N15-$E$2 -> #DIV/0!
A16: =A15+1 -> 45911 | B16: =A16 -> 45911 | C16: 4754.8387 | D16: ='Sales Management Sheet'!AK14 -> 0 | E16: =D16*$E$4 -> 0 | F16: 3 | G16: =F16*$G$4 -> 150 | H16: =C16+E16+G16 -> 4904.8387 | I16: =SUM(I15+H16) -> 53903.226 | K16: ='Sales Management Sheet'!H14 -> 0 | L16: =SUM(L15+K16) -> 0 | M16: =SUM(H16/K16) -> #DIV/0! | N16: =SUM(I16/L16) -> #DIV/0! | O16: =N16-$E$2 -> #DIV/0!
A17: =A16+1 -> 45912 | B17: =A17 -> 45912 | C17: 4754.8387 | D17: ='Sales Management Sheet'!AK15 -> 0 | E17: =D17*$E$4 -> 0 | F17: 3 | G17: =F17*$G$4 -> 150 | H17: =C17+E17+G17 -> 4904.8387 | I17: =SUM(I16+H17) -> 58808.065 | K17: ='Sales Management Sheet'!H15 -> 0 | L17: =SUM(L16+K17) -> 0 | M17: =SUM(H17/K17) -> #DIV/0! | N17: =SUM(I17/L17) -> #DIV/0! | O17: =N17-$E$2 -> #DIV/0!
A18: =A17+1 -> 45913 | B18: =A18 -> 45913 | C18: 4754.8387 | D18: ='Sales Management Sheet'!AK16 -> 0 | E18: =D18*$E$4 -> 0 | F18: 3 | G18: =F18*$G$4 -> 150 | H18: =C18+E18+G18 -> 4904.8387 | I18: =SUM(I17+H18) -> 63712.903 | K18: ='Sales Management Sheet'!H16 -> 0 | L18: =SUM(L17+K18) -> 0 | M18: =SUM(H18/K18) -> #DIV/0! | N18: =SUM(I18/L18) -> #DIV/0! | O18: =N18-$E$2 -> #DIV/0!
... A28: =A27+1 -> 45923 | B28: =A28 -> 45923 | C28: 4754.8387 | D28: ='Sales Management Sheet'!AK26 -> 0 | E28: =D28*$E$4 -> 0 | F28: 3 | G28: =F28*$G$4 -> 150 | H28: =C28+E28+G28 -> 4904.8387 | I28: =SUM(I27+H28) -> 112761.29 | K28: ='Sales Management Sheet'!H26 -> 0 | L28: =SUM(L27+K28) -> 0 | M28: =SUM(H28/K28) -> #DIV/0! | N28: =SUM(I28/L28) -> #DIV/0! | O28: =N28-$E$2 -> #DIV/0!
A29: =A28+1 -> 45924 | B29: =A29 -> 45924 | C29: 4754.8387 | D29: ='Sales Management Sheet'!AK27 -> 0 | E29: =D29*$E$4 -> 0 | G29: =F29*$G$4 -> 0 | H29: =C29+E29+G29 -> 4754.8387 | I29: =SUM(I28+H29) -> 117516.13 | K29: ='Sales Management Sheet'!H27 -> 0 | L29: =SUM(L28+K29) -> 0 | M29: =SUM(H29/K29) -> #DIV/0! | N29: =SUM(I29/L29) -> #DIV/0! | O29: =N29-$E$2 -> #DIV/0!
A30: =A29+1 -> 45925 | B30: =A30 -> 45925 | C30: 4754.8387 | D30: ='Sales Management Sheet'!AK28 -> 0 | E30: =D30*$E$4 -> 0 | G30: =F30*$G$4 -> 0 | H30: =C30+E30+G30 -> 4754.8387 | I30: =SUM(I29+H30) -> 122270.97 | K30: ='Sales Management Sheet'!H28 -> 0 | L30: =SUM(L29+K30) -> 0 | M30: =SUM(H30/K30) -> #DIV/0! | N30: =SUM(I30/L30) -> #DIV/0! | O30: =N30-$E$2 -> #DIV/0!
A31: =A30+1 -> 45926 | B31: =A31 -> 45926 | C31: 4754.8387 | D31: ='Sales Management Sheet'!AK29 -> 0 | E31: =D31*$E$4 -> 0 | G31: =F31*$G$4 -> 0 | H31: =C31+E31+G31 -> 4754.8387 | I31: =SUM(I30+H31) -> 127025.81 | K31: ='Sales Management Sheet'!H29 -> 0 | L31: =SUM(L30+K31) -> 0 | M31: =SUM(H31/K31) -> #DIV/0! | N31: =SUM(I31/L31) -> #DIV/0! | O31: =N31-$E$2 -> #DIV/0!
A32: =A31+1 -> 45927 | B32: =A32 -> 45927 | C32: 4754.8387 | D32: ='Sales Management Sheet'!AK30 -> 0 | E32: =D32*$E$4 -> 0 | G32: =F32*$G$4 -> 0 | H32: =C32+E32+G32 -> 4754.8387 | I32: =SUM(I31+H32) -> 131780.65 | K32: ='Sales Management Sheet'!H30 -> 0 | L32: =SUM(L31+K32) -> 0 | M32: =SUM(H32/K32) -> #DIV/0! | N32: =SUM(I32/L32) -> #DIV/0! | O32: =N32-$E$2 -> #DIV/0!
A33: =A32+1 -> 45928 | B33: =A33 -> 45928 | C33: 4754.8387 | D33: ='Sales Management Sheet'!AK31 -> 0 | E33: =D33*$E$4 -> 0 | G33: =F33*$G$4 -> 0 | H33: =C33+E33+G33 -> 4754.8387 | I33: =SUM(I32+H33) -> 136535.48 | K33: ='Sales Management Sheet'!H31 -> 0 | L33: =SUM(L32+K33) -> 0 | M33: =SUM(H33/K33) -> #DIV/0! | N33: =SUM(I33/L33) -> #DIV/0! | O33: =N33-$E$2 -> #DIV/0!
A34: =A33+1 -> 45929 | B34: =A34 -> 45929 | C34: 4754.8387 | D34: ='Sales Management Sheet'!AK32 -> 0 | E34: =D34*$E$4 -> 0 | G34: =F34*$G$4 -> 0 | H34: =C34+E34+G34 -> 4754.8387 | I34: =SUM(I33+H34) -> 141290.32 | K34: ='Sales Management Sheet'!H32 -> 0 | L34: =SUM(L33+K34) -> 0 | M34: =SUM(H34/K34) -> #DIV/0! | N34: =SUM(I34/L34) -> #DIV/0! | O34: =N34-$E$2 -> #DIV/0!
A35: =A34+1 -> 45930 | B35: =A35 -> 45930 | C35: 4754.8387 | D35: ='Sales Management Sheet'!AK33 -> 0 | E35: =D35*$E$4 -> 0 | G35: =F35*$G$4 -> 0 | H35: =C35+E35+G35 -> 4754.8387 | I35: =SUM(I34+H35) -> 146045.16 | K35: ='Sales Management Sheet'!H33 -> 0 | L35: =SUM(L34+K35) -> 0 | M35: =SUM(H35/K35) -> #DIV/0! | N35: =SUM(I35/L35) -> #DIV/0! | O35: =N35-$E$2 -> #DIV/0!
A36: =A35+1 -> 45931 | B36: =A36 -> 45931 | C36: 4754.8387 | D36: ='Sales Management Sheet'!AK34 -> 0 | E36: =D36*$E$4 -> 0 | G36: =F36*$G$4 -> 0 | H36: =C36+E36+G36 -> 4754.8387 | I36: =SUM(I35+H36) -> 150800 | K36: ='Sales Management Sheet'!H34 -> 0 | L36: =SUM(L35+K36) -> 0 | M36: =SUM(H36/K36) -> #DIV/0! | N36: =SUM(I36/L36) -> #DIV/0! | O36: =N36-$E$2 -> #DIV/0!
A37: Totel | C37: =SUM(C6:C36) -> 147400 | D37: =SUM(D6:D36) -> 0 | E37: =SUM(E6:E36) -> 0 | F37: =SUM(F6:F36) -> 68 | G37: =SUM(G6:G36) -> 3400 | H37: =SUM(H6:H36) -> 150800 | I37: =I36 -> 150800 | K37: =SUM(K6:K36) -> 0 | L37: =L36 -> 0 | M37: =SUM(H37/K37) -> #DIV/0! | N37: =SUM(I37/L37) -> #DIV/0! | O37: =N37-$E$2 -> #DIV/0!
M112: .

Sheet GSI สาขาที่ไม่มี Delivery
A2: GSI Ratings
A3: Store Name:
A4: Date | B4: GSI | C4: OSAT | E4: Google Review | G4: Check By
A5: 45444 | B5: =D5+F5 -> 0 | D5: =C5*67% -> 0 | F5: =E5*33% -> 0
A6: =A5+1 -> 45445 | B6: =D6+F6 -> 0 | D6: =C6*67% -> 0 | F6: =E6*33% -> 0
A7: =A6+1 -> 45446 | B7: =D7+F7 -> 0 | D7: =C7*67% -> 0 | F7: =E7*33% -> 0
A8: =A7+1 -> 45447 | B8: =D8+F8 -> 0 | D8: =C8*67% -> 0 | F8: =E8*33% -> 0
A9: =A8+1 -> 45448 | B9: =D9+F9 -> 0 | D9: =C9*67% -> 0 | F9: =E9*33% -> 0
A10: =A9+1 -> 45449 | B10: =D10+F10 -> 0 | D10: =C10*67% -> 0 | F10: =E10*33% -> 0
A11: =A10+1 -> 45450 | B11: =D11+F11 -> 0 | D11: =C11*67% -> 0 | F11: =E11*33% -> 0
A12: =A11+1 -> 45451 | B12: =D12+F12 -> 0 | D12: =C12*67% -> 0 | F12: =E12*33% -> 0
A13: =A12+1 -> 45452 | B13: =D13+F13 -> 0 | D13: =C13*67% -> 0 | F13: =E13*33% -> 0
A14: =A13+1 -> 45453 | B14: =D14+F14 -> 0 | D14: =C14*67% -> 0 | F14: =E14*33% -> 0
A15: =A14+1 -> 45454 | B15: =D15+F15 -> 0 | D15: =C15*67% -> 0 | F15: =E15*33% -> 0
A16: =A15+1 -> 45455 | B16: =D16+F16 -> 0 | D16: =C16*67% -> 0 | F16: =E16*33% -> 0
A17: =A16+1 -> 45456 | B17: =D17+F17 -> 0 | D17: =C17*67% -> 0 | F17: =E17*33% -> 0
... A35: =A34+1 -> 45474 | B35: =D35+F35 -> 0 | D35: =C35*67% -> 0 | F35: =E35*33% -> 0
A36: Average Rating | B36: =D36+F36 -> #DIV/0! | C36: =AVERAGE(C5:C35) -> #DIV/0! | D36: =C36*67% -> #DIV/0! | E36: =AVERAGE(E5:E35) -> #DIV/0! | F36: =E36*33% -> #DIV/0!

Sheet BY SEG
A1: ='Sales Management Sheet'!#REF! -> #REF!
A2: Day | B2: Date | C2: Dine In | E2: Take Away | G2: BK Delivery | I2: Drive Thru | K2: 1112Delivery | M2: lalamove | O2: foodpanda | Q2: Line Man | S2: GrabFood | U2: GET | W2: honestbee | Y2: Grand Total TC | Z2: Grand Total Sales
C3: TC | D3: Sales | E3: TC | F3: Sales | G3: TC | H3: Sales | I3: TC | J3: Sales | K3: TC | L3: Sales | M3: TC | N3: Sales | O3: TC | P3: Sales | Q3: TC | R3: Sales | S3: TC | T3: Sales | U3: TC | V3: Sales | W3: TC | X3: Sales
A4: ='Sales Management Sheet'!A4 -> 46113 | B4: ='Sales Management Sheet'!B4 -> 46113 | Y4: =SUM(C4,E4,G4,I4,K4,M4,O4,Q4,U4,W4) -> 0 | Z4: =SUM(D4,F4,H4,J4,L4,N4,P4,R4,T4,X4) -> 0
A5: ='Sales Management Sheet'!A5 -> 46114 | B5: ='Sales Management Sheet'!B5 -> 46114 | Y5: =SUM(C5,E5,G5,I5,K5,M5,O5,Q5,U5,W5) -> 0 | Z5: =SUM(C5:W5) -> 0
A6: ='Sales Management Sheet'!A6 -> 46115 | B6: ='Sales Management Sheet'!B6 -> 46115 | Y6: =SUM(C6,E6,G6,I6,K6,M6,O6,Q6,U6,W6) -> 0 | Z6: =SUM(C6:W6) -> 0
A7: ='Sales Management Sheet'!A7 -> 46116 | B7: ='Sales Management Sheet'!B7 -> 46116 | Y7: =SUM(C7,E7,G7,I7,K7,M7,O7,Q7,U7,W7) -> 0 | Z7: =SUM(C7:W7) -> 0
A8: ='Sales Management Sheet'!A8 -> 46117 | B8: ='Sales Management Sheet'!B8 -> 46117 | Y8: =SUM(C8,E8,G8,I8,K8,M8,O8,Q8,U8,W8) -> 0 | Z8: =SUM(C8:W8) -> 0
A9: ='Sales Management Sheet'!A9 -> 46118 | B9: ='Sales Management Sheet'!B9 -> 46118 | Y9: =SUM(C9,E9,G9,I9,K9,M9,O9,Q9,U9,W9) -> 0 | Z9: =SUM(C9:W9) -> 0
A10: ='Sales Management Sheet'!A10 -> 46119 | B10: ='Sales Management Sheet'!B10 -> 46119 | Y10: =SUM(C10,E10,G10,I10,K10,M10,O10,Q10,U10,W10) -> 0 | Z10: =SUM(C10:W10) -> 0
A11: ='Sales Management Sheet'!A11 -> 46120 | B11: ='Sales Management Sheet'!B11 -> 46120 | Y11: =SUM(C11,E11,G11,I11,K11,M11,O11,Q11,U11,W11) -> 0 | Z11: =SUM(C11:W11) -> 0
A12: ='Sales Management Sheet'!A12 -> 46121 | B12: ='Sales Management Sheet'!B12 -> 46121 | Y12: =SUM(C12,E12,G12,I12,K12,M12,O12,Q12,U12,W12) -> 0 | Z12: =SUM(C12:W12) -> 0
A13: ='Sales Management Sheet'!A13 -> 46122 | B13: ='Sales Management Sheet'!B13 -> 46122 | Y13: =SUM(C13,E13,G13,I13,K13,M13,O13,Q13,U13,W13) -> 0 | Z13: =SUM(C13:W13) -> 0
A14: ='Sales Management Sheet'!A14 -> 46123 | B14: ='Sales Management Sheet'!B14 -> 46123 | Y14: =SUM(C14,E14,G14,I14,K14,M14,O14,Q14,U14,W14) -> 0 | Z14: =SUM(C14:W14) -> 0
A15: ='Sales Management Sheet'!A15 -> 46124 | B15: ='Sales Management Sheet'!B15 -> 46124 | Y15: =SUM(C15,E15,G15,I15,K15,M15,O15,Q15,U15,W15) -> 0 | Z15: =SUM(C15:W15) -> 0
A16: ='Sales Management Sheet'!A16 -> 46125 | B16: ='Sales Management Sheet'!B16 -> 46125 | Y16: =SUM(C16,E16,G16,I16,K16,M16,O16,Q16,U16,W16) -> 0 | Z16: =SUM(C16:W16) -> 0
... A34: ='Sales Management Sheet'!A34 -> 46143 | B34: ='Sales Management Sheet'!B34 -> 46143 | Y34: =SUM(C34,E34,G34,I34,K34,M34,O34,Q34,U34,W34) -> 0 | Z34: =SUM(C34:W34) -> 0
A35: Grand Total MTH | C35: =SUM(C4:C34) -> 0 | D35: =SUM(D4:D34) -> 0 | E35: =SUM(E4:E34) -> 0 | F35: =SUM(F4:F34) -> 0 | G35: =SUM(G4:G34) -> 0 | H35: =SUM(H4:H34) -> 0 | I35: =SUM(I4:I34) -> 0 | J35: =SUM(J4:J34) -> 0 | ... X35: =SUM(X4:X34) -> 0 | Y35: =SUM(C35,E35,G35,I35,K35,M35,O35,Q35,U35,W35) -> 0 | Z35: =SUM(C35:W35) -> 0

Sheet Sheet1
B1: Compatibility Report for Sales Management Sheet ^0 GSI 2024 (Update).xls
B2: Run on 08/02/2025 04:25
B4: If the workbook is saved in an earlier file format or opened in an earlier version of Microsoft Excel, the listed features will not be available.
B6: Significant loss of functionality | E6: # of occurrences | F6: Version
B8: You can no longer edit this object. | E8: 2
E9: Instruction(สูตร)'!A1:D52 | F9: Excel 97-2003
F10: Excel 97-2003
B12: Some cells have overlapping conditional formatting ranges. Earlier versions of Excel will not evaluate all of the conditional formatting rules on the overlapping cells. The overlapping cells will show different conditional formatting. | E12: 1
E13: Sales Management Sheet'!S4:S34 | F13: Excel 97-2003
B15: Some cells contain conditional formatting with the 'Stop if True' option cleared. Earlier versions of Excel do not recognize this option and will stop after the first true condition. | E15: 3
E16: Sales Management Sheet'!S4:S35 | F16: Excel 97-2003
E17: Sales Management Sheet'!AS4:AS35
B20: Minor loss of fidelity
B22: Some cells or styles in this workbook contain formatting that is not supported by the selected file format. These formats will be converted to the closest format available. | E22: 98 | F22: Excel 97-2003
