Workbook

Sheet Fix Cost
A1: Labour control sheet | G1: Bangchak Phetburi
A2: Month : | B2: 45627
F3: จำนวน | G3: เงินเดือน | H3: รวม
A4: 1 | B4: MGT TEAM
C5: Manager | F5: 1 | G5: 23000 | H5: =+F5*G5 -> 23000 | J5: 6 | K5: 0.05 | L5: =H5*K5 -> 1150
C6: Assistant Manager 1 | F6: 1 | G6: 18000 | H6: =+F6*G6 -> 18000 | J6: 6 | K6: 0.05 | L6: =H6*K6 -> 900
C7: Assistant Manager 2 | F7: 1 | G7: 16000 | H7: =+F7*G7 -> 16000 | J7: 5 | K7: 0.05 | L7: =H7*K7 -> 800
C8: Assistant Manager 2 | H8: =+F8*G8 -> 0 | J8: 5 | K8: 0.05 | L8: =H8*K8 -> 0
C9: Shift Manager | F9: 1 | G9: 16000 | H9: =+F9*G9 -> 16000 | J9: 4 | K9: 0.05 | L9: =H9*K9 -> 800
C10: Shift Manager | H10: =+F10*G10 -> 0 | J10: 4 | K10: 0.05 | L10: =H10*K10 -> 0
C11: Management trainee | F11: 1 | G11: 15000 | H11: =+F11*G11 -> 15000 | J11: 4 | K11: 0.05 | L11: =H11*K11 -> 750
C12: Management trainee | H12: =+F12*G12 -> 0 | J12: 4 | K12: 0.05 | L12: =H12*K12 -> 0
A13: 2 | B13: FULL TIME COST | J13: 4 | K13: 0.05 | L13: =H13*K13 -> 0
C14: Team Leader | H14: =+F14*G14 -> 0 | J14: 4 | K14: 0.05 | L14: =H14*K14 -> 0
C15: Team Leader | H15: =+F15*G15 -> 0 | J15: 4 | K15: 0.05 | L15: =H15*K15 -> 0
C16: Full time | F16: 3 | G16: 12000 | H16: =+F16*G16 -> 36000 | J16: 4 | K16: 0.05 | L16: =H16*K16 -> 1800
C17: Full time | H17: =+F17*G17 -> 0 | J17: 4 | K17: 0.05 | L17: =H17*K17 -> 0
C18: Full time | H18: =+F18*G18 -> 0 | J18: 4 | K18: 0.05 | L18: =H18*K18 -> 0
C19: Full time | H19: =+F19*G19 -> 0 | J19: 4 | K19: 0.05 | L19: =H19*K19 -> 0
C20: Full time | H20: =+F20*G20 -> 0 | J20: 4 | K20: 0.05 | L20: =H20*K20 -> 0
A21: 3 | B21: TRAVELING - Management | F21: 5 | G21: 2000 | H21: =+F21*G21 -> 10000 | L21: =SUM(L5:L20) -> 6200
B22: รวม | H22: =SUM(H5:H21) -> 134000
A24: 4 | B24: PROVIDENT FUND (* % of salary 1+2) | H24: =L21 -> 6200
A25: 5 | B25: Diligent South
A26: 6 | B26: Housing Allowance
A27: 7 | B27: SOCIAL SECURITY (** 5% of salary 1+2) | H27: =H24 -> 6200
A28: 8 | B28: Over Night Shift Allow.
A29: 9 | B29: Allowance Transportation
A30: 10 | B30: BONUS 8.33% | J30: Forecast Sales MTD : | K30: 2000000 | L30: Budget COL | M30: 0.14
A31: 11 | B31: Medical + Uniform | J31: Budget COL | K31: hire P/T (฿)
A32: 12 | B32: Incentive (Sales & Store con.) | J32: =K30*M30 -> 280000 | K32: =J32-H34 -> 132600 | L32: =K32/'COL Daily'!E4 -> 2652 | M32: hours/month
A33: 13 | B33: Work man compensation | H33: 1000 | L33: =L32/H35 -> 85.548387 | M33: hours/day
C34: TOTALL FIX COST | H34: =SUM(H22:H33) -> 147400 | K34: Part time | L34: =L33/8 -> 10.693548 | M34: persons/day
F35: Number of days | H35: 31 | K35: FT | L35: =SUM(F14:F20) -> 3 | M35: persons/day
F36: Fixed cost per day | H36: =+H34/H35 -> 4754.8387 | J36: Total | L36: =L34+L35 -> 13.693548 | M36: persons/day
B38: * | C38: Year with Minor | E38: 0-4 year | F38: 0.05
E39: 4-6 year | F39: 0.07
E40: 6-7 year | F40: 0.08
E41: 7-8 year | F41: 0.09
E42: >8 year | F42: 0.1
...

Sheet COL Daily
A1: ='Fix Cost'!A1:D1 -> Labour control sheet
A2: Month : | C2: 45870 | D2: Budget | E2: ='Fix Cost'!M30 -> 0.14
A4: Avg. per hour | E4: 50 | F4: ค่ารถ Close shift | G4: 50
A5: Date | B5: Day | C5: Fix cost (Full time) | D5: Total Hrs (Part Time) | E5: Cost | F5: จำนวนคนปิดร้าน | G5: Close shift | H5: COL(day) | I5: Accum. COL | K5: Sales(day) | L5: Sales MTD | M5: % Daily | N5: MTD % total | O5: VAR
A6: =C2 -> 45870 | B6: =A6 -> 45870 | C6: ='Fix Cost'!$H$36 -> 4754.8387 | E6: =D6*$E$4 -> 0 | G6: =F6*$G$4 -> 0 | H6: =C6+E6+G6 -> 4754.8387 | I6: =H6 -> 4754.8387 | L6: =K6 -> 0 | M6: =SUM(H6/K6) -> #DIV/0! | N6: =SUM(I6/L6) -> #DIV/0! | O6: =N6-$E$2 -> #DIV/0!
A7: =A6+1 -> 45871 | B7: =A7 -> 45871 | C7: ='Fix Cost'!$H$36 -> 4754.8387 | E7: =D7*$E$4 -> 0 | G7: =F7*$G$4 -> 0 | H7: =C7+E7+G7 -> 4754.8387 | I7: =SUM(I6+H7) -> 9509.6774 | L7: =SUM(L6+K7) -> 0 | M7: =SUM(H7/K7) -> #DIV/0! | N7: =SUM(I7/L7) -> #DIV/0! | O7: =N7-$E$2 -> #DIV/0!
A8: =A7+1 -> 45872 | B8: =A8 -> 45872 | C8: ='Fix Cost'!$H$36 -> 4754.8387 | E8: =D8*$E$4 -> 0 | G8: =F8*$G$4 -> 0 | H8: =C8+E8+G8 -> 4754.8387 | I8: =SUM(I7+H8) -> 14264.516 | L8: =SUM(L7+K8) -> 0 | M8: =SUM(H8/K8) -> #DIV/0! | N8: =SUM(I8/L8) -> #DIV/0! | O8: =N8-$E$2 -> #DIV/0!
A9: =A8+1 -> 45873 | B9: =A9 -> 45873 | C9: ='Fix Cost'!$H$36 -> 4754.8387 | E9: =D9*$E$4 -> 0 | G9: =F9*$G$4 -> 0 | H9: =C9+E9+G9 -> 4754.8387 | I9: =SUM(I8+H9) -> 19019.355 | L9: =SUM(L8+K9) -> 0 | M9: =SUM(H9/K9) -> #DIV/0! | N9: =SUM(I9/L9) -> #DIV/0! | O9: =N9-$E$2 -> #DIV/0!
A10: =A9+1 -> 45874 | B10: =A10 -> 45874 | C10: ='Fix Cost'!$H$36 -> 4754.8387 | E10: =D10*$E$4 -> 0 | G10: =F10*$G$4 -> 0 | H10: =C10+E10+G10 -> 4754.8387 | I10: =SUM(I9+H10) -> 23774.194 | L10: =SUM(L9+K10) -> 0 | M10: =SUM(H10/K10) -> #DIV/0! | N10: =SUM(I10/L10) -> #DIV/0! | O10: =N10-$E$2 -> #DIV/0!
A11: =A10+1 -> 45875 | B11: =A11 -> 45875 | C11: ='Fix Cost'!$H$36 -> 4754.8387 | E11: =D11*$E$4 -> 0 | G11: =F11*$G$4 -> 0 | H11: =C11+E11+G11 -> 4754.8387 | I11: =SUM(I10+H11) -> 28529.032 | L11: =SUM(L10+K11) -> 0 | M11: =SUM(H11/K11) -> #DIV/0! | N11: =SUM(I11/L11) -> #DIV/0! | O11: =N11-$E$2 -> #DIV/0!
A12: =A11+1 -> 45876 | B12: =A12 -> 45876 | C12: ='Fix Cost'!$H$36 -> 4754.8387 | E12: =D12*$E$4 -> 0 | G12: =F12*$G$4 -> 0 | H12: =C12+E12+G12 -> 4754.8387 | I12: =SUM(I11+H12) -> 33283.871 | L12: =SUM(L11+K12) -> 0 | M12: =SUM(H12/K12) -> #DIV/0! | N12: =SUM(I12/L12) -> #DIV/0! | O12: =N12-$E$2 -> #DIV/0!
A13: =A12+1 -> 45877 | B13: =A13 -> 45877 | C13: ='Fix Cost'!$H$36 -> 4754.8387 | E13: =D13*$E$4 -> 0 | G13: =F13*$G$4 -> 0 | H13: =C13+E13+G13 -> 4754.8387 | I13: =SUM(I12+H13) -> 38038.71 | L13: =SUM(L12+K13) -> 0 | M13: =SUM(H13/K13) -> #DIV/0! | N13: =SUM(I13/L13) -> #DIV/0! | O13: =N13-$E$2 -> #DIV/0!
A14: =A13+1 -> 45878 | B14: =A14 -> 45878 | C14: ='Fix Cost'!$H$36 -> 4754.8387 | E14: =D14*$E$4 -> 0 | G14: =F14*$G$4 -> 0 | H14: =C14+E14+G14 -> 4754.8387 | I14: =SUM(I13+H14) -> 42793.548 | L14: =SUM(L13+K14) -> 0 | M14: =SUM(H14/K14) -> #DIV/0! | N14: =SUM(I14/L14) -> #DIV/0! | O14: =N14-$E$2 -> #DIV/0!
A15: =A14+1 -> 45879 | B15: =A15 -> 45879 | C15: ='Fix Cost'!$H$36 -> 4754.8387 | E15: =D15*$E$4 -> 0 | G15: =F15*$G$4 -> 0 | H15: =C15+E15+G15 -> 4754.8387 | I15: =SUM(I14+H15) -> 47548.387 | L15: =SUM(L14+K15) -> 0 | M15: =SUM(H15/K15) -> #DIV/0! | N15: =SUM(I15/L15) -> #DIV/0! | O15: =N15-$E$2 -> #DIV/0!
A16: =A15+1 -> 45880 | B16: =A16 -> 45880 | C16: ='Fix Cost'!$H$36 -> 4754.8387 | E16: =D16*$E$4 -> 0 | G16: =F16*$G$4 -> 0 | H16: =C16+E16+G16 -> 4754.8387 | I16: =SUM(I15+H16) -> 52303.226 | L16: =SUM(L15+K16) -> 0 | M16: =SUM(H16/K16) -> #DIV/0! | N16: =SUM(I16/L16) -> #DIV/0! | O16: =N16-$E$2 -> #DIV/0!
A17: =A16+1 -> 45881 | B17: =A17 -> 45881 | C17: ='Fix Cost'!$H$36 -> 4754.8387 | E17: =D17*$E$4 -> 0 | G17: =F17*$G$4 -> 0 | H17: =C17+E17+G17 -> 4754.8387 | I17: =SUM(I16+H17) -> 57058.065 | L17: =SUM(L16+K17) -> 0 | M17: =SUM(H17/K17) -> #DIV/0! | N17: =SUM(I17/L17) -> #DIV/0! | O17: =N17-$E$2 -> #DIV/0!
A18: =A17+1 -> 45882 | B18: =A18 -> 45882 | C18: ='Fix Cost'!$H$36 -> 4754.8387 | E18: =D18*$E$4 -> 0 | G18: =F18*$G$4 -> 0 | H18: =C18+E18+G18 -> 4754.8387 | I18: =SUM(I17+H18) -> 61812.903 | L18: =SUM(L17+K18) -> 0 | M18: =SUM(H18/K18) -> #DIV/0! | N18: =SUM(I18/L18) -> #DIV/0! | O18: =N18-$E$2 -> #DIV/0!
... A36: =A35+1 -> 45900 | B36: =A36 -> 45900 | C36: ='Fix Cost'!$H$36 -> 4754.8387 | E36: =D36*$E$4 -> 0 | G36: =F36*$G$4 -> 0 | H36: =C36+E36+G36 -> 4754.8387 | I36: =SUM(I35+H36) -> 147400 | L36: =SUM(L35+K36) -> 0 | M36: =SUM(H36/K36) -> #DIV/0! | N36: =SUM(I36/L36) -> #DIV/0! | O36: =N36-$E$2 -> #DIV/0!
A37: Totel | C37: =SUM(C6:C36) -> 147400 | D37: =SUM(D6:D36) -> 0 | E37: =SUM(E6:E36) -> 0 | F37: =SUM(F6:F36) -> 0 | G37: =SUM(G6:G36) -> 0 | H37: =SUM(H6:H36) -> 147400 | I37: =I36 -> 147400 | K37: =SUM(K6:K36) -> 0 | L37: =L36 -> 0 | M37: =SUM(H37/K37) -> #DIV/0! | N37: =SUM(I37/L37) -> #DIV/0! | O37: =N37-$E$2 -> #DIV/0!
M112: .
